Workbook

Sheet Comece Aqui
A1: Panela no Lucro · Planilha de Custo, Preço e Pedidos
A2: Funciona no Excel, no Google Planilhas e no LibreOffice. Os valores de exemplo são da cozinha fictícia 'Cozinha da Cláudia' e servem só para você ver tudo funcionando.
A4: COR DAS CÉLULAS
A5: Amarelo claro | B5: você preenche
A6: Verde claro | B6: a planilha calcula. Não apague as fórmulas.
A8: ORDEM DE USO (veja o Guia, Dias 1 a 7)
A9: 1. Config | B9: Seus números: valor da sua hora, margem, gás, combustível, taxas e custos fixos do mês.
A10: 2. Ingredientes | B10: Tudo o que você compra, com o preço que pagou e o tamanho do pacote.
A11: 3. Fichas | B11: Cada receita, linha por linha: ingrediente e quantidade usada.
A12: 4. Produtos | B12: Rendimento, embalagem e tempo. Mostra o custo real, o preço mínimo, o preço sugerido e a situação do seu preço atual.
A13: 5. Entrega | B13: Seus bairros e distâncias. Mostra o custo real de cada entrega e a taxa sugerida.
A14: 6. Pedidos | B14: Anote cada pedido. A planilha calcula taxa, custo e lucro de cada um.
A15: 7. Semana | B15: Quantas unidades vai produzir. Gera a lista de compras na aba Ingredientes (coluna 'Comprar p/ semana').
A16: 8. Painel | B16: Escolha o mês: faturamento, lucro real, dinheiro que ficou com você e quanto você ganhou por hora.
A18: PARA COMEÇAR DO ZERO | B18: Apague só as células AMARELAS de exemplo (Ingredientes, Fichas, Produtos, Entrega e Pedidos) e digite as suas. Não apague linhas inteiras.
A19: IMPORTANTE | B19: O nome do produto na aba Produtos tem de ser IGUAL ao nome da receita na aba Fichas (mesma grafia).

Sheet Painel
A1: 8. Painel do mês
A2: Escolha o mês e o ano (células amarelas). Considera só pedidos não cancelados. Encomendas futuras do mês entram como previsão.
B4: Mês (1 a 12) | C4: 10
B5: Ano | C5: 2026
B6: Horas que você trabalhou no negócio no mês (cozinhar, comprar, entregar, atender) | C6: 52
B8: Pedidos no mês | C8: =COUNTIFS(Pedidos!$R$4:$R$503,$C$4,Pedidos!$S$4:$S$503,$C$5,Pedidos!$K$4:$K$503,">0")
B9: Faturamento (tudo que o cliente pagou) | C9: =SUMIFS(Pedidos!$K$4:$K$503,Pedidos!$R$4:$R$503,$C$4,Pedidos!$S$4:$S$503,$C$5)
B10: (-) Taxas de operadora e app | C10: =SUMIFS(Pedidos!$L$4:$L$503,Pedidos!$R$4:$R$503,$C$4,Pedidos!$S$4:$S$503,$C$5)
B11: (-) Material (ingrediente, embalagem, gás) | C11: =SUMIFS(Pedidos!$M$4:$M$503,Pedidos!$R$4:$R$503,$C$4,Pedidos!$S$4:$S$503,$C$5)
B12: (-) Entregas | C12: =SUMIFS(Pedidos!$O$4:$O$503,Pedidos!$R$4:$R$503,$C$4,Pedidos!$S$4:$S$503,$C$5)
B13: (-) Custos fixos do mês (aba Config) | C13: =Config!$C$30
B14: → DINHEIRO QUE SOBROU PARA VOCÊ | C14: =C9-C10-C11-C12-C13
B15: Sua hora já paga dentro disso (valor da hora × horas planejadas nas receitas) | C15: =SUMIFS(Pedidos!$N$4:$N$503,Pedidos!$R$4:$R$503,$C$4,Pedidos!$S$4:$S$503,$C$5)
B16: → LUCRO DO NEGÓCIO (o que sobra depois de pagar a sua hora) | C16: =C14-C15
B17: Ticket médio por pedido | C17: =IF(C8>0,C9/C8,0)
B18: VOCÊ GANHOU POR HORA DE TRABALHO REAL | C18: =IF(N(C6)>0,C14/C6,0)
B19: Meta: valor da sua hora (Config) | C19: =Config!$C$4
B20: Diagnóstico | C20: =IF(C9=0,"Sem pedidos neste mês",IF(C14<0,"PREJUÍZO: você pagou para trabalhar. Revise preços (aba Produtos) e fixos.",IF(C18<C19,"Sobrou dinheiro, mas sua hora real ficou ABAIXO da meta. Veja o tempo gasto e o lucro por produto.","Saudável: a hora real está igual ou acima da meta.")))
B21: Falta receber (encomendas e sinais) | C21: =SUMIFS(Pedidos!$Q$4:$Q$503,Pedidos!$R$4:$R$503,$C$4,Pedidos!$S$4:$S$503,$C$5)
B22: Lucro por produto no mês (descubra o que vale a pena vender)
B23: Produto | C23: Unidades vendidas | D23: Faturamento | E23: Lucro do negócio | F23: Lucro por unidade
B24: =IF(Produtos!A4="","",Produtos!A4) | C24: =IF(B24="","",SUMIFS(Pedidos!$D$4:$D$503,Pedidos!$C$4:$C$503,B24,Pedidos!$R$4:$R$503,$C$4,Pedidos!$S$4:$S$503,$C$5)) | D24: =IF(B24="","",SUMIFS(Pedidos!$K$4:$K$503,Pedidos!$C$4:$C$503,B24,Pedidos!$R$4:$R$503,$C$4,Pedidos!$S$4:$S$503,$C$5)) | E24: =IF(B24="","",SUMIFS(Pedidos!$P$4:$P$503,Pedidos!$C$4:$C$503,B24,Pedidos!$R$4:$R$503,$C$4,Pedidos!$S$4:$S$503,$C$5)) | F24: =IF(OR(B24="",N(C24)=0),"",E24/C24)
B25: =IF(Produtos!A5="","",Produtos!A5) | C25: =IF(B25="","",SUMIFS(Pedidos!$D$4:$D$503,Pedidos!$C$4:$C$503,B25,Pedidos!$R$4:$R$503,$C$4,Pedidos!$S$4:$S$503,$C$5)) | D25: =IF(B25="","",SUMIFS(Pedidos!$K$4:$K$503,Pedidos!$C$4:$C$503,B25,Pedidos!$R$4:$R$503,$C$4,Pedidos!$S$4:$S$503,$C$5)) | E25: =IF(B25="","",SUMIFS(Pedidos!$P$4:$P$503,Pedidos!$C$4:$C$503,B25,Pedidos!$R$4:$R$503,$C$4,Pedidos!$S$4:$S$503,$C$5)) | F25: =IF(OR(B25="",N(C25)=0),"",E25/C25)
B26: =IF(Produtos!A6="","",Produtos!A6) | C26: =IF(B26="","",SUMIFS(Pedidos!$D$4:$D$503,Pedidos!$C$4:$C$503,B26,Pedidos!$R$4:$R$503,$C$4,Pedidos!$S$4:$S$503,$C$5)) | D26: =IF(B26="","",SUMIFS(Pedidos!$K$4:$K$503,Pedidos!$C$4:$C$503,B26,Pedidos!$R$4:$R$503,$C$4,Pedidos!$S$4:$S$503,$C$5)) | E26: =IF(B26="","",SUMIFS(Pedidos!$P$4:$P$503,Pedidos!$C$4:$C$503,B26,Pedidos!$R$4:$R$503,$C$4,Pedidos!$S$4:$S$503,$C$5)) | F26: =IF(OR(B26="",N(C26)=0),"",E26/C26)
B27: =IF(Produtos!A7="","",Produtos!A7) | C27: =IF(B27="","",SUMIFS(Pedidos!$D$4:$D$503,Pedidos!$C$4:$C$503,B27,Pedidos!$R$4:$R$503,$C$4,Pedidos!$S$4:$S$503,$C$5)) | D27: =IF(B27="","",SUMIFS(Pedidos!$K$4:$K$503,Pedidos!$C$4:$C$503,B27,Pedidos!$R$4:$R$503,$C$4,Pedidos!$S$4:$S$503,$C$5)) | E27: =IF(B27="","",SUMIFS(Pedidos!$P$4:$P$503,Pedidos!$C$4:$C$503,B27,Pedidos!$R$4:$R$503,$C$4,Pedidos!$S$4:$S$503,$C$5)) | F27: =IF(OR(B27="",N(C27)=0),"",E27/C27)
B28: =IF(Produtos!A8="","",Produtos!A8) | C28: =IF(B28="","",SUMIFS(Pedidos!$D$4:$D$503,Pedidos!$C$4:$C$503,B28,Pedidos!$R$4:$R$503,$C$4,Pedidos!$S$4:$S$503,$C$5)) | D28: =IF(B28="","",SUMIFS(Pedidos!$K$4:$K$503,Pedidos!$C$4:$C$503,B28,Pedidos!$R$4:$R$503,$C$4,Pedidos!$S$4:$S$503,$C$5)) | E28: =IF(B28="","",SUMIFS(Pedidos!$P$4:$P$503,Pedidos!$C$4:$C$503,B28,Pedidos!$R$4:$R$503,$C$4,Pedidos!$S$4:$S$503,$C$5)) | F28: =IF(OR(B28="",N(C28)=0),"",E28/C28)
B29: =IF(Produtos!A9="","",Produtos!A9) | C29: =IF(B29="","",SUMIFS(Pedidos!$D$4:$D$503,Pedidos!$C$4:$C$503,B29,Pedidos!$R$4:$R$503,$C$4,Pedidos!$S$4:$S$503,$C$5)) | D29: =IF(B29="","",SUMIFS(Pedidos!$K$4:$K$503,Pedidos!$C$4:$C$503,B29,Pedidos!$R$4:$R$503,$C$4,Pedidos!$S$4:$S$503,$C$5)) | E29: =IF(B29="","",SUMIFS(Pedidos!$P$4:$P$503,Pedidos!$C$4:$C$503,B29,Pedidos!$R$4:$R$503,$C$4,Pedidos!$S$4:$S$503,$C$5)) | F29: =IF(OR(B29="",N(C29)=0),"",E29/C29)
B30: =IF(Produtos!A10="","",Produtos!A10) | C30: =IF(B30="","",SUMIFS(Pedidos!$D$4:$D$503,Pedidos!$C$4:$C$503,B30,Pedidos!$R$4:$R$503,$C$4,Pedidos!$S$4:$S$503,$C$5)) | D30: =IF(B30="","",SUMIFS(Pedidos!$K$4:$K$503,Pedidos!$C$4:$C$503,B30,Pedidos!$R$4:$R$503,$C$4,Pedidos!$S$4:$S$503,$C$5)) | E30: =IF(B30="","",SUMIFS(Pedidos!$P$4:$P$503,Pedidos!$C$4:$C$503,B30,Pedidos!$R$4:$R$503,$C$4,Pedidos!$S$4:$S$503,$C$5)) | F30: =IF(OR(B30="",N(C30)=0),"",E30/C30)
B31: =IF(Produtos!A11="","",Produtos!A11) | C31: =IF(B31="","",SUMIFS(Pedidos!$D$4:$D$503,Pedidos!$C$4:$C$503,B31,Pedidos!$R$4:$R$503,$C$4,Pedidos!$S$4:$S$503,$C$5)) | D31: =IF(B31="","",SUMIFS(Pedidos!$K$4:$K$503,Pedidos!$C$4:$C$503,B31,Pedidos!$R$4:$R$503,$C$4,Pedidos!$S$4:$S$503,$C$5)) | E31: =IF(B31="","",SUMIFS(Pedidos!$P$4:$P$503,Pedidos!$C$4:$C$503,B31,Pedidos!$R$4:$R$503,$C$4,Pedidos!$S$4:$S$503,$C$5)) | F31: =IF(OR(B31="",N(C31)=0),"",E31/C31)
B32: =IF(Produtos!A12="","",Produtos!A12) | C32: =IF(B32="","",SUMIFS(Pedidos!$D$4:$D$503,Pedidos!$C$4:$C$503,B32,Pedidos!$R$4:$R$503,$C$4,Pedidos!$S$4:$S$503,$C$5)) | D32: =IF(B32="","",SUMIFS(Pedidos!$K$4:$K$503,Pedidos!$C$4:$C$503,B32,Pedidos!$R$4:$R$503,$C$4,Pedidos!$S$4:$S$503,$C$5)) | E32: =IF(B32="","",SUMIFS(Pedidos!$P$4:$P$503,Pedidos!$C$4:$C$503,B32,Pedidos!$R$4:$R$503,$C$4,Pedidos!$S$4:$S$503,$C$5)) | F32: =IF(OR(B32="",N(C32)=0),"",E32/C32)
B33: =IF(Produtos!A13="","",Produtos!A13) | C33: =IF(B33="","",SUMIFS(Pedidos!$D$4:$D$503,Pedidos!$C$4:$C$503,B33,Pedidos!$R$4:$R$503,$C$4,Pedidos!$S$4:$S$503,$C$5)) | D33: =IF(B33="","",SUMIFS(Pedidos!$K$4:$K$503,Pedidos!$C$4:$C$503,B33,Pedidos!$R$4:$R$503,$C$4,Pedidos!$S$4:$S$503,$C$5)) | E33: =IF(B33="","",SUMIFS(Pedidos!$P$4:$P$503,Pedidos!$C$4:$C$503,B33,Pedidos!$R$4:$R$503,$C$4,Pedidos!$S$4:$S$503,$C$5)) | F33: =IF(OR(B33="",N(C33)=0),"",E33/C33)
B34: =IF(Produtos!A14="","",Produtos!A14) | C34: =IF(B34="","",SUMIFS(Pedidos!$D$4:$D$503,Pedidos!$C$4:$C$503,B34,Pedidos!$R$4:$R$503,$C$4,Pedidos!$S$4:$S$503,$C$5)) | D34: =IF(B34="","",SUMIFS(Pedidos!$K$4:$K$503,Pedidos!$C$4:$C$503,B34,Pedidos!$R$4:$R$503,$C$4,Pedidos!$S$4:$S$503,$C$5)) | E34: =IF(B34="","",SUMIFS(Pedidos!$P$4:$P$503,Pedidos!$C$4:$C$503,B34,Pedidos!$R$4:$R$503,$C$4,Pedidos!$S$4:$S$503,$C$5)) | F34: =IF(OR(B34="",N(C34)=0),"",E34/C34)
B35: =IF(Produtos!A15="","",Produtos!A15) | C35: =IF(B35="","",SUMIFS(Pedidos!$D$4:$D$503,Pedidos!$C$4:$C$503,B35,Pedidos!$R$4:$R$503,$C$4,Pedidos!$S$4:$S$503,$C$5)) | D35: =IF(B35="","",SUMIFS(Pedidos!$K$4:$K$503,Pedidos!$C$4:$C$503,B35,Pedidos!$R$4:$R$503,$C$4,Pedidos!$S$4:$S$503,$C$5)) | E35: =IF(B35="","",SUMIFS(Pedidos!$P$4:$P$503,Pedidos!$C$4:$C$503,B35,Pedidos!$R$4:$R$503,$C$4,Pedidos!$S$4:$S$503,$C$5)) | F35: =IF(OR(B35="",N(C35)=0),"",E35/C35)
... B38: =IF(Produtos!A18="","",Produtos!A18) | C38: =IF(B38="","",SUMIFS(Pedidos!$D$4:$D$503,Pedidos!$C$4:$C$503,B38,Pedidos!$R$4:$R$503,$C$4,Pedidos!$S$4:$S$503,$C$5)) | D38: =IF(B38="","",SUMIFS(Pedidos!$K$4:$K$503,Pedidos!$C$4:$C$503,B38,Pedidos!$R$4:$R$503,$C$4,Pedidos!$S$4:$S$503,$C$5)) | E38: =IF(B38="","",SUMIFS(Pedidos!$P$4:$P$503,Pedidos!$C$4:$C$503,B38,Pedidos!$R$4:$R$503,$C$4,Pedidos!$S$4:$S$503,$C$5)) | F38: =IF(OR(B38="",N(C38)=0),"",E38/C38)
B40: Obs.: o 'lucro do pedido' (aba Pedidos) não desconta os custos fixos. Eles são descontados uma vez por mês, aqui no painel.

Sheet Config
A1: 1. Configurações
A2: Preencha uma vez e revise todo mês, ou quando o gás ou o combustível mudarem de preço.
B4: Quanto vale 1 hora do seu trabalho (R$) | C4: 15 | D4: Use pelo menos o que você ganharia por hora em outro trabalho. Com R$ 1.518/mês e 220 h, a hora sai a ~R$ 6,90. Muita gente usa entre R$ 12 e R$ 20.
B5: Margem de lucro desejada (% do preço) | C5: 0.2 | D5: É o que sobra para o NEGÓCIO depois de pagar tudo, inclusive a sua hora. Entre 15% e 30% é comum. Não passe de 50%.
B6: Preço do botijão de gás (R$) | C6: 125 | D6: Preço que você pagou no último botijão.
B7: Horas de 1 boca acesa que o botijão dura | C7: 60 | D7: Para medir: anote o dia da troca e quantas horas de boca usou (forno = 3 bocas). Sem medir, use 60.
B8: Custo do gás por hora de boca (R$) | C8: =C6/C7
B9: Preço do combustível (R$/litro) | C9: 6.2 | D9: Para entregas próprias.
B10: Consumo do veículo (km por litro) | C10: 35 | D10: Moto ~30–40; carro ~9–12.
B11: Desgaste e manutenção por km (R$) | C11: 0.15 | D11: Pneu, óleo, revisão. Moto ~R$ 0,10–0,20; carro ~R$ 0,30–0,50.
B12: Custo real por km rodado (R$) | C12: =C9/C10+C11
B14: TAXAS DE RECEBIMENTO (% que fica com a operadora) | D14: Confira no extrato da sua maquininha ou do app.
B15: Pix | C15: 0
B16: Dinheiro | C16: 0
B17: Cartão de débito | C17: 0.019
B18: Cartão de crédito | C18: 0.039
B19: App de delivery | C19: 0.27 | D19: Comissão + taxa de pagamento. Confira no contrato do seu plano.
B20: Taxa média usada no preço de balcão | C20: 0.01 | D20: Se quase tudo é Pix, use 0% a 1%. Se muito é crédito, use ~3%.
B22: CUSTOS FIXOS DO MÊS (o que você paga vendendo pouco ou muito)
B23: Aumento estimado na conta de luz | C23: 40 | D23: Compare a conta de agora com a de antes de começar a vender.
B24: Aumento estimado na conta de água | C24: 20
B25: Parte do celular/internet usada no negócio | C25: 30
B26: Guia mensal do MEI (DAS), se tiver | C26: 82 | D26: Confira o valor do ano no Portal do Empreendedor. Se não for MEI, ponha 0.
B27: Divulgação (impulsionamento, panfleto) | C27: 0
B28: Reposição de utensílios (panela, forma), por mês | C28: 30 | D28: Ex.: R$ 360 por ano / 12.
B29: Outros fixos | C29: 0
B30: TOTAL DE CUSTOS FIXOS DO MÊS | C30: =SUM(C23:C29)
B31: Faturamento que você espera no mês (R$) | C31: 3000 | D31: Seja realista: use a média dos últimos meses. Se está começando, chute baixo.
B32: Peso dos fixos no preço (% do faturamento) | C32: =IF(C31>0,C30/C31,0) | D32: Se passar de 15%, seus fixos estão pesados para o tanto que você vende.
B34: Alerta: | C34: =IF(C5+C20+C32>=0.9,"ERRO: margem + taxa + fixos passam de 90%. Reduza a margem ou os fixos.","OK")

Sheet Ingredientes
A1: 2. Ingredientes, embalagens e insumos
A2: Preço de EXEMPLO (out/2026). Troque pelo preço que VOCÊ pagou. Use g para peso, ml para líquidos e un para unidades.
A3: Item | B3: Unidade (g, ml, un) | C3: Quantidade do pacote | D3: Preço pago (R$) | E3: Custo por unidade (R$) | F3: Comprar p/ semana (na unidade) | G3: Pacotes a comprar
A4: Arroz | B4: g | C4: 5000 | D4: 27.9 | E4: =IF(AND(ISNUMBER(C4),C4>0,ISNUMBER(D4)),D4/C4,"") | F4: =IF(A4="","",SUMIF(Fichas!$B$4:$B$603,A4,Fichas!$F$4:$F$603)) | G4: =IF(OR(A4="",F4="",N(C4)=0),"",ROUNDUP(F4/C4,0))
A5: Feijão carioca | B5: g | C5: 1000 | D5: 8.49 | E5: =IF(AND(ISNUMBER(C5),C5>0,ISNUMBER(D5)),D5/C5,"") | F5: =IF(A5="","",SUMIF(Fichas!$B$4:$B$603,A5,Fichas!$F$4:$F$603)) | G5: =IF(OR(A5="",F5="",N(C5)=0),"",ROUNDUP(F5/C5,0))
A6: Peito de frango | B6: g | C6: 1000 | D6: 19.9 | E6: =IF(AND(ISNUMBER(C6),C6>0,ISNUMBER(D6)),D6/C6,"") | F6: =IF(A6="","",SUMIF(Fichas!$B$4:$B$603,A6,Fichas!$F$4:$F$603)) | G6: =IF(OR(A6="",F6="",N(C6)=0),"",ROUNDUP(F6/C6,0))
A7: Carne moída | B7: g | C7: 1000 | D7: 38.9 | E7: =IF(AND(ISNUMBER(C7),C7>0,ISNUMBER(D7)),D7/C7,"") | F7: =IF(A7="","",SUMIF(Fichas!$B$4:$B$603,A7,Fichas!$F$4:$F$603)) | G7: =IF(OR(A7="",F7="",N(C7)=0),"",ROUNDUP(F7/C7,0))
A8: Óleo de soja | B8: ml | C8: 900 | D8: 7.99 | E8: =IF(AND(ISNUMBER(C8),C8>0,ISNUMBER(D8)),D8/C8,"") | F8: =IF(A8="","",SUMIF(Fichas!$B$4:$B$603,A8,Fichas!$F$4:$F$603)) | G8: =IF(OR(A8="",F8="",N(C8)=0),"",ROUNDUP(F8/C8,0))
A9: Alho | B9: g | C9: 200 | D9: 6.5 | E9: =IF(AND(ISNUMBER(C9),C9>0,ISNUMBER(D9)),D9/C9,"") | F9: =IF(A9="","",SUMIF(Fichas!$B$4:$B$603,A9,Fichas!$F$4:$F$603)) | G9: =IF(OR(A9="",F9="",N(C9)=0),"",ROUNDUP(F9/C9,0))
A10: Cebola | B10: g | C10: 1000 | D10: 5.99 | E10: =IF(AND(ISNUMBER(C10),C10>0,ISNUMBER(D10)),D10/C10,"") | F10: =IF(A10="","",SUMIF(Fichas!$B$4:$B$603,A10,Fichas!$F$4:$F$603)) | G10: =IF(OR(A10="",F10="",N(C10)=0),"",ROUNDUP(F10/C10,0))
A11: Sal | B11: g | C11: 1000 | D11: 3.29 | E11: =IF(AND(ISNUMBER(C11),C11>0,ISNUMBER(D11)),D11/C11,"") | F11: =IF(A11="","",SUMIF(Fichas!$B$4:$B$603,A11,Fichas!$F$4:$F$603)) | G11: =IF(OR(A11="",F11="",N(C11)=0),"",ROUNDUP(F11/C11,0))
A12: Tomate | B12: g | C12: 1000 | D12: 7.99 | E12: =IF(AND(ISNUMBER(C12),C12>0,ISNUMBER(D12)),D12/C12,"") | F12: =IF(A12="","",SUMIF(Fichas!$B$4:$B$603,A12,Fichas!$F$4:$F$603)) | G12: =IF(OR(A12="",F12="",N(C12)=0),"",ROUNDUP(F12/C12,0))
A13: Cenoura | B13: g | C13: 1000 | D13: 4.99 | E13: =IF(AND(ISNUMBER(C13),C13>0,ISNUMBER(D13)),D13/C13,"") | F13: =IF(A13="","",SUMIF(Fichas!$B$4:$B$603,A13,Fichas!$F$4:$F$603)) | G13: =IF(OR(A13="",F13="",N(C13)=0),"",ROUNDUP(F13/C13,0))
A14: Farinha de trigo | B14: g | C14: 1000 | D14: 5.49 | E14: =IF(AND(ISNUMBER(C14),C14>0,ISNUMBER(D14)),D14/C14,"") | F14: =IF(A14="","",SUMIF(Fichas!$B$4:$B$603,A14,Fichas!$F$4:$F$603)) | G14: =IF(OR(A14="",F14="",N(C14)=0),"",ROUNDUP(F14/C14,0))
A15: Leite integral | B15: ml | C15: 1000 | D15: 5.29 | E15: =IF(AND(ISNUMBER(C15),C15>0,ISNUMBER(D15)),D15/C15,"") | F15: =IF(A15="","",SUMIF(Fichas!$B$4:$B$603,A15,Fichas!$F$4:$F$603)) | G15: =IF(OR(A15="",F15="",N(C15)=0),"",ROUNDUP(F15/C15,0))
... A29: Etiqueta/adesivo | B29: un | C29: 100 | D29: 12 | E29: =IF(AND(ISNUMBER(C29),C29>0,ISNUMBER(D29)),D29/C29,"") | F29: =IF(A29="","",SUMIF(Fichas!$B$4:$B$603,A29,Fichas!$F$4:$F$603)) | G29: =IF(OR(A29="",F29="",N(C29)=0),"",ROUNDUP(F29/C29,0))
E30: =IF(AND(ISNUMBER(C30),C30>0,ISNUMBER(D30)),D30/C30,"") | F30: =IF(A30="","",SUMIF(Fichas!$B$4:$B$603,A30,Fichas!$F$4:$F$603)) | G30: =IF(OR(A30="",F30="",N(C30)=0),"",ROUNDUP(F30/C30,0))
E31: =IF(AND(ISNUMBER(C31),C31>0,ISNUMBER(D31)),D31/C31,"") | F31: =IF(A31="","",SUMIF(Fichas!$B$4:$B$603,A31,Fichas!$F$4:$F$603)) | G31: =IF(OR(A31="",F31="",N(C31)=0),"",ROUNDUP(F31/C31,0))
E32: =IF(AND(ISNUMBER(C32),C32>0,ISNUMBER(D32)),D32/C32,"") | F32: =IF(A32="","",SUMIF(Fichas!$B$4:$B$603,A32,Fichas!$F$4:$F$603)) | G32: =IF(OR(A32="",F32="",N(C32)=0),"",ROUNDUP(F32/C32,0))
E33: =IF(AND(ISNUMBER(C33),C33>0,ISNUMBER(D33)),D33/C33,"") | F33: =IF(A33="","",SUMIF(Fichas!$B$4:$B$603,A33,Fichas!$F$4:$F$603)) | G33: =IF(OR(A33="",F33="",N(C33)=0),"",ROUNDUP(F33/C33,0))
E34: =IF(AND(ISNUMBER(C34),C34>0,ISNUMBER(D34)),D34/C34,"") | F34: =IF(A34="","",SUMIF(Fichas!$B$4:$B$603,A34,Fichas!$F$4:$F$603)) | G34: =IF(OR(A34="",F34="",N(C34)=0),"",ROUNDUP(F34/C34,0))
E35: =IF(AND(ISNUMBER(C35),C35>0,ISNUMBER(D35)),D35/C35,"") | F35: =IF(A35="","",SUMIF(Fichas!$B$4:$B$603,A35,Fichas!$F$4:$F$603)) | G35: =IF(OR(A35="",F35="",N(C35)=0),"",ROUNDUP(F35/C35,0))
E36: =IF(AND(ISNUMBER(C36),C36>0,ISNUMBER(D36)),D36/C36,"") | F36: =IF(A36="","",SUMIF(Fichas!$B$4:$B$603,A36,Fichas!$F$4:$F$603)) | G36: =IF(OR(A36="",F36="",N(C36)=0),"",ROUNDUP(F36/C36,0))
E37: =IF(AND(ISNUMBER(C37),C37>0,ISNUMBER(D37)),D37/C37,"") | F37: =IF(A37="","",SUMIF(Fichas!$B$4:$B$603,A37,Fichas!$F$4:$F$603)) | G37: =IF(OR(A37="",F37="",N(C37)=0),"",ROUNDUP(F37/C37,0))
E38: =IF(AND(ISNUMBER(C38),C38>0,ISNUMBER(D38)),D38/C38,"") | F38: =IF(A38="","",SUMIF(Fichas!$B$4:$B$603,A38,Fichas!$F$4:$F$603)) | G38: =IF(OR(A38="",F38="",N(C38)=0),"",ROUNDUP(F38/C38,0))
E39: =IF(AND(ISNUMBER(C39),C39>0,ISNUMBER(D39)),D39/C39,"") | F39: =IF(A39="","",SUMIF(Fichas!$B$4:$B$603,A39,Fichas!$F$4:$F$603)) | G39: =IF(OR(A39="",F39="",N(C39)=0),"",ROUNDUP(F39/C39,0))
E40: =IF(AND(ISNUMBER(C40),C40>0,ISNUMBER(D40)),D40/C40,"") | F40: =IF(A40="","",SUMIF(Fichas!$B$4:$B$603,A40,Fichas!$F$4:$F$603)) | G40: =IF(OR(A40="",F40="",N(C40)=0),"",ROUNDUP(F40/C40,0))
E41: =IF(AND(ISNUMBER(C41),C41>0,ISNUMBER(D41)),D41/C41,"") | F41: =IF(A41="","",SUMIF(Fichas!$B$4:$B$603,A41,Fichas!$F$4:$F$603)) | G41: =IF(OR(A41="",F41="",N(C41)=0),"",ROUNDUP(F41/C41,0))
... E203: =IF(AND(ISNUMBER(C203),C203>0,ISNUMBER(D203)),D203/C203,"") | F203: =IF(A203="","",SUMIF(Fichas!$B$4:$B$603,A203,Fichas!$F$4:$F$603)) | G203: =IF(OR(A203="",F203="",N(C203)=0),"",ROUNDUP(F203/C203,0))

Sheet Fichas
A1: 3. Fichas técnicas (receitas)
A2: Uma linha por ingrediente. Escreva o nome da receita igual em todas as linhas dela. Quantidade na MESMA unidade da aba Ingredientes. Inclua só o que vai na receita; a embalagem por unidade vai na aba Produtos.
A3: Receita (= nome do produto) | B3: Ingrediente (escolha da lista) | C3: Quantidade usada | D3: Unidade | E3: Custo na receita (R$) | F3: Quantidade p/ a semana
A4: Marmita frango grelhado | B4: Arroz | C4: 1000 | D4: =IF(B4="","",IFERROR(VLOOKUP(B4,Ingredientes!$A$4:$E$203,2,0),"?")) | E4: =IF(B4="","",IFERROR(VLOOKUP(B4,Ingredientes!$A$4:$E$203,5,0)*C4,"ITEM NÃO CADASTRADO")) | F4: =IF(A4="","",IFERROR(C4*VLOOKUP(A4,Semana!$A$5:$E$54,5,0),0))
A5: Marmita frango grelhado | B5: Feijão carioca | C5: 500 | D5: =IF(B5="","",IFERROR(VLOOKUP(B5,Ingredientes!$A$4:$E$203,2,0),"?")) | E5: =IF(B5="","",IFERROR(VLOOKUP(B5,Ingredientes!$A$4:$E$203,5,0)*C5,"ITEM NÃO CADASTRADO")) | F5: =IF(A5="","",IFERROR(C5*VLOOKUP(A5,Semana!$A$5:$E$54,5,0),0))
A6: Marmita frango grelhado | B6: Peito de frango | C6: 1500 | D6: =IF(B6="","",IFERROR(VLOOKUP(B6,Ingredientes!$A$4:$E$203,2,0),"?")) | E6: =IF(B6="","",IFERROR(VLOOKUP(B6,Ingredientes!$A$4:$E$203,5,0)*C6,"ITEM NÃO CADASTRADO")) | F6: =IF(A6="","",IFERROR(C6*VLOOKUP(A6,Semana!$A$5:$E$54,5,0),0))
A7: Marmita frango grelhado | B7: Óleo de soja | C7: 120 | D7: =IF(B7="","",IFERROR(VLOOKUP(B7,Ingredientes!$A$4:$E$203,2,0),"?")) | E7: =IF(B7="","",IFERROR(VLOOKUP(B7,Ingredientes!$A$4:$E$203,5,0)*C7,"ITEM NÃO CADASTRADO")) | F7: =IF(A7="","",IFERROR(C7*VLOOKUP(A7,Semana!$A$5:$E$54,5,0),0))
A8: Marmita frango grelhado | B8: Alho | C8: 30 | D8: =IF(B8="","",IFERROR(VLOOKUP(B8,Ingredientes!$A$4:$E$203,2,0),"?")) | E8: =IF(B8="","",IFERROR(VLOOKUP(B8,Ingredientes!$A$4:$E$203,5,0)*C8,"ITEM NÃO CADASTRADO")) | F8: =IF(A8="","",IFERROR(C8*VLOOKUP(A8,Semana!$A$5:$E$54,5,0),0))
A9: Marmita frango grelhado | B9: Cebola | C9: 200 | D9: =IF(B9="","",IFERROR(VLOOKUP(B9,Ingredientes!$A$4:$E$203,2,0),"?")) | E9: =IF(B9="","",IFERROR(VLOOKUP(B9,Ingredientes!$A$4:$E$203,5,0)*C9,"ITEM NÃO CADASTRADO")) | F9: =IF(A9="","",IFERROR(C9*VLOOKUP(A9,Semana!$A$5:$E$54,5,0),0))
A10: Marmita frango grelhado | B10: Sal | C10: 30 | D10: =IF(B10="","",IFERROR(VLOOKUP(B10,Ingredientes!$A$4:$E$203,2,0),"?")) | E10: =IF(B10="","",IFERROR(VLOOKUP(B10,Ingredientes!$A$4:$E$203,5,0)*C10,"ITEM NÃO CADASTRADO")) | F10: =IF(A10="","",IFERROR(C10*VLOOKUP(A10,Semana!$A$5:$E$54,5,0),0))
A11: Marmita frango grelhado | B11: Tomate | C11: 400 | D11: =IF(B11="","",IFERROR(VLOOKUP(B11,Ingredientes!$A$4:$E$203,2,0),"?")) | E11: =IF(B11="","",IFERROR(VLOOKUP(B11,Ingredientes!$A$4:$E$203,5,0)*C11,"ITEM NÃO CADASTRADO")) | F11: =IF(A11="","",IFERROR(C11*VLOOKUP(A11,Semana!$A$5:$E$54,5,0),0))
A12: Marmita frango grelhado | B12: Cenoura | C12: 300 | D12: =IF(B12="","",IFERROR(VLOOKUP(B12,Ingredientes!$A$4:$E$203,2,0),"?")) | E12: =IF(B12="","",IFERROR(VLOOKUP(B12,Ingredientes!$A$4:$E$203,5,0)*C12,"ITEM NÃO CADASTRADO")) | F12: =IF(A12="","",IFERROR(C12*VLOOKUP(A12,Semana!$A$5:$E$54,5,0),0))
A13: Coxinha de frango (unid.) | B13: Peito de frango | C13: 1000 | D13: =IF(B13="","",IFERROR(VLOOKUP(B13,Ingredientes!$A$4:$E$203,2,0),"?")) | E13: =IF(B13="","",IFERROR(VLOOKUP(B13,Ingredientes!$A$4:$E$203,5,0)*C13,"ITEM NÃO CADASTRADO")) | F13: =IF(A13="","",IFERROR(C13*VLOOKUP(A13,Semana!$A$5:$E$54,5,0),0))
A14: Coxinha de frango (unid.) | B14: Farinha de trigo | C14: 1000 | D14: =IF(B14="","",IFERROR(VLOOKUP(B14,Ingredientes!$A$4:$E$203,2,0),"?")) | E14: =IF(B14="","",IFERROR(VLOOKUP(B14,Ingredientes!$A$4:$E$203,5,0)*C14,"ITEM NÃO CADASTRADO")) | F14: =IF(A14="","",IFERROR(C14*VLOOKUP(A14,Semana!$A$5:$E$54,5,0),0))
A15: Coxinha de frango (unid.) | B15: Leite integral | C15: 1000 | D15: =IF(B15="","",IFERROR(VLOOKUP(B15,Ingredientes!$A$4:$E$203,2,0),"?")) | E15: =IF(B15="","",IFERROR(VLOOKUP(B15,Ingredientes!$A$4:$E$203,5,0)*C15,"ITEM NÃO CADASTRADO")) | F15: =IF(A15="","",IFERROR(C15*VLOOKUP(A15,Semana!$A$5:$E$54,5,0),0))
... A29: Brigadeiro gourmet (unid.) | B29: Forminha nº 4 (cento) | C29: 40 | D29: =IF(B29="","",IFERROR(VLOOKUP(B29,Ingredientes!$A$4:$E$203,2,0),"?")) | E29: =IF(B29="","",IFERROR(VLOOKUP(B29,Ingredientes!$A$4:$E$203,5,0)*C29,"ITEM NÃO CADASTRADO")) | F29: =IF(A29="","",IFERROR(C29*VLOOKUP(A29,Semana!$A$5:$E$54,5,0),0))
D30: =IF(B30="","",IFERROR(VLOOKUP(B30,Ingredientes!$A$4:$E$203,2,0),"?")) | E30: =IF(B30="","",IFERROR(VLOOKUP(B30,Ingredientes!$A$4:$E$203,5,0)*C30,"ITEM NÃO CADASTRADO")) | F30: =IF(A30="","",IFERROR(C30*VLOOKUP(A30,Semana!$A$5:$E$54,5,0),0))
D31: =IF(B31="","",IFERROR(VLOOKUP(B31,Ingredientes!$A$4:$E$203,2,0),"?")) | E31: =IF(B31="","",IFERROR(VLOOKUP(B31,Ingredientes!$A$4:$E$203,5,0)*C31,"ITEM NÃO CADASTRADO")) | F31: =IF(A31="","",IFERROR(C31*VLOOKUP(A31,Semana!$A$5:$E$54,5,0),0))
D32: =IF(B32="","",IFERROR(VLOOKUP(B32,Ingredientes!$A$4:$E$203,2,0),"?")) | E32: =IF(B32="","",IFERROR(VLOOKUP(B32,Ingredientes!$A$4:$E$203,5,0)*C32,"ITEM NÃO CADASTRADO")) | F32: =IF(A32="","",IFERROR(C32*VLOOKUP(A32,Semana!$A$5:$E$54,5,0),0))
D33: =IF(B33="","",IFERROR(VLOOKUP(B33,Ingredientes!$A$4:$E$203,2,0),"?")) | E33: =IF(B33="","",IFERROR(VLOOKUP(B33,Ingredientes!$A$4:$E$203,5,0)*C33,"ITEM NÃO CADASTRADO")) | F33: =IF(A33="","",IFERROR(C33*VLOOKUP(A33,Semana!$A$5:$E$54,5,0),0))
D34: =IF(B34="","",IFERROR(VLOOKUP(B34,Ingredientes!$A$4:$E$203,2,0),"?")) | E34: =IF(B34="","",IFERROR(VLOOKUP(B34,Ingredientes!$A$4:$E$203,5,0)*C34,"ITEM NÃO CADASTRADO")) | F34: =IF(A34="","",IFERROR(C34*VLOOKUP(A34,Semana!$A$5:$E$54,5,0),0))
D35: =IF(B35="","",IFERROR(VLOOKUP(B35,Ingredientes!$A$4:$E$203,2,0),"?")) | E35: =IF(B35="","",IFERROR(VLOOKUP(B35,Ingredientes!$A$4:$E$203,5,0)*C35,"ITEM NÃO CADASTRADO")) | F35: =IF(A35="","",IFERROR(C35*VLOOKUP(A35,Semana!$A$5:$E$54,5,0),0))
D36: =IF(B36="","",IFERROR(VLOOKUP(B36,Ingredientes!$A$4:$E$203,2,0),"?")) | E36: =IF(B36="","",IFERROR(VLOOKUP(B36,Ingredientes!$A$4:$E$203,5,0)*C36,"ITEM NÃO CADASTRADO")) | F36: =IF(A36="","",IFERROR(C36*VLOOKUP(A36,Semana!$A$5:$E$54,5,0),0))
D37: =IF(B37="","",IFERROR(VLOOKUP(B37,Ingredientes!$A$4:$E$203,2,0),"?")) | E37: =IF(B37="","",IFERROR(VLOOKUP(B37,Ingredientes!$A$4:$E$203,5,0)*C37,"ITEM NÃO CADASTRADO")) | F37: =IF(A37="","",IFERROR(C37*VLOOKUP(A37,Semana!$A$5:$E$54,5,0),0))
D38: =IF(B38="","",IFERROR(VLOOKUP(B38,Ingredientes!$A$4:$E$203,2,0),"?")) | E38: =IF(B38="","",IFERROR(VLOOKUP(B38,Ingredientes!$A$4:$E$203,5,0)*C38,"ITEM NÃO CADASTRADO")) | F38: =IF(A38="","",IFERROR(C38*VLOOKUP(A38,Semana!$A$5:$E$54,5,0),0))
D39: =IF(B39="","",IFERROR(VLOOKUP(B39,Ingredientes!$A$4:$E$203,2,0),"?")) | E39: =IF(B39="","",IFERROR(VLOOKUP(B39,Ingredientes!$A$4:$E$203,5,0)*C39,"ITEM NÃO CADASTRADO")) | F39: =IF(A39="","",IFERROR(C39*VLOOKUP(A39,Semana!$A$5:$E$54,5,0),0))
D40: =IF(B40="","",IFERROR(VLOOKUP(B40,Ingredientes!$A$4:$E$203,2,0),"?")) | E40: =IF(B40="","",IFERROR(VLOOKUP(B40,Ingredientes!$A$4:$E$203,5,0)*C40,"ITEM NÃO CADASTRADO")) | F40: =IF(A40="","",IFERROR(C40*VLOOKUP(A40,Semana!$A$5:$E$54,5,0),0))
D41: =IF(B41="","",IFERROR(VLOOKUP(B41,Ingredientes!$A$4:$E$203,2,0),"?")) | E41: =IF(B41="","",IFERROR(VLOOKUP(B41,Ingredientes!$A$4:$E$203,5,0)*C41,"ITEM NÃO CADASTRADO")) | F41: =IF(A41="","",IFERROR(C41*VLOOKUP(A41,Semana!$A$5:$E$54,5,0),0))
... D603: =IF(B603="","",IFERROR(VLOOKUP(B603,Ingredientes!$A$4:$E$203,2,0),"?")) | E603: =IF(B603="","",IFERROR(VLOOKUP(B603,Ingredientes!$A$4:$E$203,5,0)*C603,"ITEM NÃO CADASTRADO")) | F603: =IF(A603="","",IFERROR(C603*VLOOKUP(A603,Semana!$A$5:$E$54,5,0),0))

Sheet Produtos
A1: 4. Produtos e preços
A2: Custo real por unidade vendida e três preços: MÍNIMO (paga tudo, inclusive a sua hora, sem lucro), SUGERIDO (com a sua margem) e no APP.
A3: Produto (= nome da receita) | B3: Rende quantas unidades | C3: Custo dos ingredientes da receita | D3: Embalagem por unidade (R$) | E3: Minutos de boca acesa na receita | F3: Minutos de trabalho na receita | G3: Ingredientes por unidade | H3: Gás por unidade | I3: CUSTO DE MATERIAL por unidade | J3: Sua hora por unidade | K3: CUSTO TOTAL por unidade | L3: PREÇO MÍNIMO | M3: PREÇO SUGERIDO | N3: Preço sugerido no APP | O3: Seu preço atual (R$) | P3: Lucro por unidade no preço atual | Q3: Dinheiro p/ você por unidade (hora + lucro) | R3: SITUAÇÃO
A4: Marmita frango grelhado | B4: 10 | C4: =IF(A4="","",SUMIF(Fichas!$A$4:$A$603,A4,Fichas!$E$4:$E$603)) | D4: 1.2 | E4: 90 | F4: 120 | G4: =IF(AND(A4<>"",N(B4)>0),C4/B4,"") | H4: =IF(AND(A4<>"",N(B4)>0),N(E4)/60*Config!$C$8/B4,"") | I4: =IF(AND(A4<>"",N(B4)>0),G4+N(D4)+H4,"") | J4: =IF(AND(A4<>"",N(B4)>0),N(F4)/60*Config!$C$4/B4,"") | K4: =IF(AND(A4<>"",N(B4)>0),I4+J4,"") | L4: =IF(AND(A4<>"",N(B4)>0),ROUNDUP(K4/(1-Config!$C$20-Config!$C$32)*10,0)/10,"") | M4: =IF(AND(A4<>"",N(B4)>0),ROUNDUP(K4/(1-Config!$C$5-Config!$C$20-Config!$C$32)*2,0)/2,"") | N4: =IF(AND(A4<>"",N(B4)>0),IF((1-Config!$C$5-Config!$C$19-Config!$C$32)<=0,"MARGEM ALTA DEMAIS",ROUNDUP(K4/(1-Config!$C$5-Config!$C$19-Config!$C$32)*2,0)/2),"") | O4: 22 | P4: =IF(AND(AND(A4<>"",N(B4)>0),N(O4)>0),O4*(1-Config!$C$20-Config!$C$32)-K4,"") | Q4: =IF(P4="","",P4+J4) | R4: =IF(P4="","",IF(O4<L4,"PREJUÍZO: abaixo do mínimo",IF(O4<M4,"Atenção: abaixo do sugerido","OK: preço saudável")))
A5: Coxinha de frango (unid.) | B5: 50 | C5: =IF(A5="","",SUMIF(Fichas!$A$4:$A$603,A5,Fichas!$E$4:$E$603)) | D5: 0.26 | E5: 150 | F5: 240 | G5: =IF(AND(A5<>"",N(B5)>0),C5/B5,"") | H5: =IF(AND(A5<>"",N(B5)>0),N(E5)/60*Config!$C$8/B5,"") | I5: =IF(AND(A5<>"",N(B5)>0),G5+N(D5)+H5,"") | J5: =IF(AND(A5<>"",N(B5)>0),N(F5)/60*Config!$C$4/B5,"") | K5: =IF(AND(A5<>"",N(B5)>0),I5+J5,"") | L5: =IF(AND(A5<>"",N(B5)>0),ROUNDUP(K5/(1-Config!$C$20-Config!$C$32)*10,0)/10,"") | M5: =IF(AND(A5<>"",N(B5)>0),ROUNDUP(K5/(1-Config!$C$5-Config!$C$20-Config!$C$32)*2,0)/2,"") | N5: =IF(AND(A5<>"",N(B5)>0),IF((1-Config!$C$5-Config!$C$19-Config!$C$32)<=0,"MARGEM ALTA DEMAIS",ROUNDUP(K5/(1-Config!$C$5-Config!$C$19-Config!$C$32)*2,0)/2),"") | O5: 4 | P5: =IF(AND(AND(A5<>"",N(B5)>0),N(O5)>0),O5*(1-Config!$C$20-Config!$C$32)-K5,"") | Q5: =IF(P5="","",P5+J5) | R5: =IF(P5="","",IF(O5<L5,"PREJUÍZO: abaixo do mínimo",IF(O5<M5,"Atenção: abaixo do sugerido","OK: preço saudável")))
A6: Brigadeiro gourmet (unid.) | B6: 40 | C6: =IF(A6="","",SUMIF(Fichas!$A$4:$A$603,A6,Fichas!$E$4:$E$603)) | D6: 0.1 | E6: 30 | F6: 120 | G6: =IF(AND(A6<>"",N(B6)>0),C6/B6,"") | H6: =IF(AND(A6<>"",N(B6)>0),N(E6)/60*Config!$C$8/B6,"") | I6: =IF(AND(A6<>"",N(B6)>0),G6+N(D6)+H6,"") | J6: =IF(AND(A6<>"",N(B6)>0),N(F6)/60*Config!$C$4/B6,"") | K6: =IF(AND(A6<>"",N(B6)>0),I6+J6,"") | L6: =IF(AND(A6<>"",N(B6)>0),ROUNDUP(K6/(1-Config!$C$20-Config!$C$32)*10,0)/10,"") | M6: =IF(AND(A6<>"",N(B6)>0),ROUNDUP(K6/(1-Config!$C$5-Config!$C$20-Config!$C$32)*2,0)/2,"") | N6: =IF(AND(A6<>"",N(B6)>0),IF((1-Config!$C$5-Config!$C$19-Config!$C$32)<=0,"MARGEM ALTA DEMAIS",ROUNDUP(K6/(1-Config!$C$5-Config!$C$19-Config!$C$32)*2,0)/2),"") | O6: 2.5 | P6: =IF(AND(AND(A6<>"",N(B6)>0),N(O6)>0),O6*(1-Config!$C$20-Config!$C$32)-K6,"") | Q6: =IF(P6="","",P6+J6) | R6: =IF(P6="","",IF(O6<L6,"PREJUÍZO: abaixo do mínimo",IF(O6<M6,"Atenção: abaixo do sugerido","OK: preço saudável")))
C7: =IF(A7="","",SUMIF(Fichas!$A$4:$A$603,A7,Fichas!$E$4:$E$603)) | G7: =IF(AND(A7<>"",N(B7)>0),C7/B7,"") | H7: =IF(AND(A7<>"",N(B7)>0),N(E7)/60*Config!$C$8/B7,"") | I7: =IF(AND(A7<>"",N(B7)>0),G7+N(D7)+H7,"") | J7: =IF(AND(A7<>"",N(B7)>0),N(F7)/60*Config!$C$4/B7,"") | K7: =IF(AND(A7<>"",N(B7)>0),I7+J7,"") | L7: =IF(AND(A7<>"",N(B7)>0),ROUNDUP(K7/(1-Config!$C$20-Config!$C$32)*10,0)/10,"") | M7: =IF(AND(A7<>"",N(B7)>0),ROUNDUP(K7/(1-Config!$C$5-Config!$C$20-Config!$C$32)*2,0)/2,"") | N7: =IF(AND(A7<>"",N(B7)>0),IF((1-Config!$C$5-Config!$C$19-Config!$C$32)<=0,"MARGEM ALTA DEMAIS",ROUNDUP(K7/(1-Config!$C$5-Config!$C$19-Config!$C$32)*2,0)/2),"") | P7: =IF(AND(AND(A7<>"",N(B7)>0),N(O7)>0),O7*(1-Config!$C$20-Config!$C$32)-K7,"") | Q7: =IF(P7="","",P7+J7) | R7: =IF(P7="","",IF(O7<L7,"PREJUÍZO: abaixo do mínimo",IF(O7<M7,"Atenção: abaixo do sugerido","OK: preço saudável")))
C8: =IF(A8="","",SUMIF(Fichas!$A$4:$A$603,A8,Fichas!$E$4:$E$603)) | G8: =IF(AND(A8<>"",N(B8)>0),C8/B8,"") | H8: =IF(AND(A8<>"",N(B8)>0),N(E8)/60*Config!$C$8/B8,"") | I8: =IF(AND(A8<>"",N(B8)>0),G8+N(D8)+H8,"") | J8: =IF(AND(A8<>"",N(B8)>0),N(F8)/60*Config!$C$4/B8,"") | K8: =IF(AND(A8<>"",N(B8)>0),I8+J8,"") | L8: =IF(AND(A8<>"",N(B8)>0),ROUNDUP(K8/(1-Config!$C$20-Config!$C$32)*10,0)/10,"") | M8: =IF(AND(A8<>"",N(B8)>0),ROUNDUP(K8/(1-Config!$C$5-Config!$C$20-Config!$C$32)*2,0)/2,"") | N8: =IF(AND(A8<>"",N(B8)>0),IF((1-Config!$C$5-Config!$C$19-Config!$C$32)<=0,"MARGEM ALTA DEMAIS",ROUNDUP(K8/(1-Config!$C$5-Config!$C$19-Config!$C$32)*2,0)/2),"") | P8: =IF(AND(AND(A8<>"",N(B8)>0),N(O8)>0),O8*(1-Config!$C$20-Config!$C$32)-K8,"") | Q8: =IF(P8="","",P8+J8) | R8: =IF(P8="","",IF(O8<L8,"PREJUÍZO: abaixo do mínimo",IF(O8<M8,"Atenção: abaixo do sugerido","OK: preço saudável")))
C9: =IF(A9="","",SUMIF(Fichas!$A$4:$A$603,A9,Fichas!$E$4:$E$603)) | G9: =IF(AND(A9<>"",N(B9)>0),C9/B9,"") | H9: =IF(AND(A9<>"",N(B9)>0),N(E9)/60*Config!$C$8/B9,"") | I9: =IF(AND(A9<>"",N(B9)>0),G9+N(D9)+H9,"") | J9: =IF(AND(A9<>"",N(B9)>0),N(F9)/60*Config!$C$4/B9,"") | K9: =IF(AND(A9<>"",N(B9)>0),I9+J9,"") | L9: =IF(AND(A9<>"",N(B9)>0),ROUNDUP(K9/(1-Config!$C$20-Config!$C$32)*10,0)/10,"") | M9: =IF(AND(A9<>"",N(B9)>0),ROUNDUP(K9/(1-Config!$C$5-Config!$C$20-Config!$C$32)*2,0)/2,"") | N9: =IF(AND(A9<>"",N(B9)>0),IF((1-Config!$C$5-Config!$C$19-Config!$C$32)<=0,"MARGEM ALTA DEMAIS",ROUNDUP(K9/(1-Config!$C$5-Config!$C$19-Config!$C$32)*2,0)/2),"") | P9: =IF(AND(AND(A9<>"",N(B9)>0),N(O9)>0),O9*(1-Config!$C$20-Config!$C$32)-K9,"") | Q9: =IF(P9="","",P9+J9) | R9: =IF(P9="","",IF(O9<L9,"PREJUÍZO: abaixo do mínimo",IF(O9<M9,"Atenção: abaixo do sugerido","OK: preço saudável")))
C10: =IF(A10="","",SUMIF(Fichas!$A$4:$A$603,A10,Fichas!$E$4:$E$603)) | G10: =IF(AND(A10<>"",N(B10)>0),C10/B10,"") | H10: =IF(AND(A10<>"",N(B10)>0),N(E10)/60*Config!$C$8/B10,"") | I10: =IF(AND(A10<>"",N(B10)>0),G10+N(D10)+H10,"") | J10: =IF(AND(A10<>"",N(B10)>0),N(F10)/60*Config!$C$4/B10,"") | K10: =IF(AND(A10<>"",N(B10)>0),I10+J10,"") | L10: =IF(AND(A10<>"",N(B10)>0),ROUNDUP(K10/(1-Config!$C$20-Config!$C$32)*10,0)/10,"") | M10: =IF(AND(A10<>"",N(B10)>0),ROUNDUP(K10/(1-Config!$C$5-Config!$C$20-Config!$C$32)*2,0)/2,"") | N10: =IF(AND(A10<>"",N(B10)>0),IF((1-Config!$C$5-Config!$C$19-Config!$C$32)<=0,"MARGEM ALTA DEMAIS",ROUNDUP(K10/(1-Config!$C$5-Config!$C$19-Config!$C$32)*2,0)/2),"") | P10: =IF(AND(AND(A10<>"",N(B10)>0),N(O10)>0),O10*(1-Config!$C$20-Config!$C$32)-K10,"") | Q10: =IF(P10="","",P10+J10) | R10: =IF(P10="","",IF(O10<L10,"PREJUÍZO: abaixo do mínimo",IF(O10<M10,"Atenção: abaixo do sugerido","OK: preço saudável")))
C11: =IF(A11="","",SUMIF(Fichas!$A$4:$A$603,A11,Fichas!$E$4:$E$603)) | G11: =IF(AND(A11<>"",N(B11)>0),C11/B11,"") | H11: =IF(AND(A11<>"",N(B11)>0),N(E11)/60*Config!$C$8/B11,"") | I11: =IF(AND(A11<>"",N(B11)>0),G11+N(D11)+H11,"") | J11: =IF(AND(A11<>"",N(B11)>0),N(F11)/60*Config!$C$4/B11,"") | K11: =IF(AND(A11<>"",N(B11)>0),I11+J11,"") | L11: =IF(AND(A11<>"",N(B11)>0),ROUNDUP(K11/(1-Config!$C$20-Config!$C$32)*10,0)/10,"") | M11: =IF(AND(A11<>"",N(B11)>0),ROUNDUP(K11/(1-Config!$C$5-Config!$C$20-Config!$C$32)*2,0)/2,"") | N11: =IF(AND(A11<>"",N(B11)>0),IF((1-Config!$C$5-Config!$C$19-Config!$C$32)<=0,"MARGEM ALTA DEMAIS",ROUNDUP(K11/(1-Config!$C$5-Config!$C$19-Config!$C$32)*2,0)/2),"") | P11: =IF(AND(AND(A11<>"",N(B11)>0),N(O11)>0),O11*(1-Config!$C$20-Config!$C$32)-K11,"") | Q11: =IF(P11="","",P11+J11) | R11: =IF(P11="","",IF(O11<L11,"PREJUÍZO: abaixo do mínimo",IF(O11<M11,"Atenção: abaixo do sugerido","OK: preço saudável")))
C12: =IF(A12="","",SUMIF(Fichas!$A$4:$A$603,A12,Fichas!$E$4:$E$603)) | G12: =IF(AND(A12<>"",N(B12)>0),C12/B12,"") | H12: =IF(AND(A12<>"",N(B12)>0),N(E12)/60*Config!$C$8/B12,"") | I12: =IF(AND(A12<>"",N(B12)>0),G12+N(D12)+H12,"") | J12: =IF(AND(A12<>"",N(B12)>0),N(F12)/60*Config!$C$4/B12,"") | K12: =IF(AND(A12<>"",N(B12)>0),I12+J12,"") | L12: =IF(AND(A12<>"",N(B12)>0),ROUNDUP(K12/(1-Config!$C$20-Config!$C$32)*10,0)/10,"") | M12: =IF(AND(A12<>"",N(B12)>0),ROUNDUP(K12/(1-Config!$C$5-Config!$C$20-Config!$C$32)*2,0)/2,"") | N12: =IF(AND(A12<>"",N(B12)>0),IF((1-Config!$C$5-Config!$C$19-Config!$C$32)<=0,"MARGEM ALTA DEMAIS",ROUNDUP(K12/(1-Config!$C$5-Config!$C$19-Config!$C$32)*2,0)/2),"") | P12: =IF(AND(AND(A12<>"",N(B12)>0),N(O12)>0),O12*(1-Config!$C$20-Config!$C$32)-K12,"") | Q12: =IF(P12="","",P12+J12) | R12: =IF(P12="","",IF(O12<L12,"PREJUÍZO: abaixo do mínimo",IF(O12<M12,"Atenção: abaixo do sugerido","OK: preço saudável")))
C13: =IF(A13="","",SUMIF(Fichas!$A$4:$A$603,A13,Fichas!$E$4:$E$603)) | G13: =IF(AND(A13<>"",N(B13)>0),C13/B13,"") | H13: =IF(AND(A13<>"",N(B13)>0),N(E13)/60*Config!$C$8/B13,"") | I13: =IF(AND(A13<>"",N(B13)>0),G13+N(D13)+H13,"") | J13: =IF(AND(A13<>"",N(B13)>0),N(F13)/60*Config!$C$4/B13,"") | K13: =IF(AND(A13<>"",N(B13)>0),I13+J13,"") | L13: =IF(AND(A13<>"",N(B13)>0),ROUNDUP(K13/(1-Config!$C$20-Config!$C$32)*10,0)/10,"") | M13: =IF(AND(A13<>"",N(B13)>0),ROUNDUP(K13/(1-Config!$C$5-Config!$C$20-Config!$C$32)*2,0)/2,"") | N13: =IF(AND(A13<>"",N(B13)>0),IF((1-Config!$C$5-Config!$C$19-Config!$C$32)<=0,"MARGEM ALTA DEMAIS",ROUNDUP(K13/(1-Config!$C$5-Config!$C$19-Config!$C$32)*2,0)/2),"") | P13: =IF(AND(AND(A13<>"",N(B13)>0),N(O13)>0),O13*(1-Config!$C$20-Config!$C$32)-K13,"") | Q13: =IF(P13="","",P13+J13) | R13: =IF(P13="","",IF(O13<L13,"PREJUÍZO: abaixo do mínimo",IF(O13<M13,"Atenção: abaixo do sugerido","OK: preço saudável")))
C14: =IF(A14="","",SUMIF(Fichas!$A$4:$A$603,A14,Fichas!$E$4:$E$603)) | G14: =IF(AND(A14<>"",N(B14)>0),C14/B14,"") | H14: =IF(AND(A14<>"",N(B14)>0),N(E14)/60*Config!$C$8/B14,"") | I14: =IF(AND(A14<>"",N(B14)>0),G14+N(D14)+H14,"") | J14: =IF(AND(A14<>"",N(B14)>0),N(F14)/60*Config!$C$4/B14,"") | K14: =IF(AND(A14<>"",N(B14)>0),I14+J14,"") | L14: =IF(AND(A14<>"",N(B14)>0),ROUNDUP(K14/(1-Config!$C$20-Config!$C$32)*10,0)/10,"") | M14: =IF(AND(A14<>"",N(B14)>0),ROUNDUP(K14/(1-Config!$C$5-Config!$C$20-Config!$C$32)*2,0)/2,"") | N14: =IF(AND(A14<>"",N(B14)>0),IF((1-Config!$C$5-Config!$C$19-Config!$C$32)<=0,"MARGEM ALTA DEMAIS",ROUNDUP(K14/(1-Config!$C$5-Config!$C$19-Config!$C$32)*2,0)/2),"") | P14: =IF(AND(AND(A14<>"",N(B14)>0),N(O14)>0),O14*(1-Config!$C$20-Config!$C$32)-K14,"") | Q14: =IF(P14="","",P14+J14) | R14: =IF(P14="","",IF(O14<L14,"PREJUÍZO: abaixo do mínimo",IF(O14<M14,"Atenção: abaixo do sugerido","OK: preço saudável")))
C15: =IF(A15="","",SUMIF(Fichas!$A$4:$A$603,A15,Fichas!$E$4:$E$603)) | G15: =IF(AND(A15<>"",N(B15)>0),C15/B15,"") | H15: =IF(AND(A15<>"",N(B15)>0),N(E15)/60*Config!$C$8/B15,"") | I15: =IF(AND(A15<>"",N(B15)>0),G15+N(D15)+H15,"") | J15: =IF(AND(A15<>"",N(B15)>0),N(F15)/60*Config!$C$4/B15,"") | K15: =IF(AND(A15<>"",N(B15)>0),I15+J15,"") | L15: =IF(AND(A15<>"",N(B15)>0),ROUNDUP(K15/(1-Config!$C$20-Config!$C$32)*10,0)/10,"") | M15: =IF(AND(A15<>"",N(B15)>0),ROUNDUP(K15/(1-Config!$C$5-Config!$C$20-Config!$C$32)*2,0)/2,"") | N15: =IF(AND(A15<>"",N(B15)>0),IF((1-Config!$C$5-Config!$C$19-Config!$C$32)<=0,"MARGEM ALTA DEMAIS",ROUNDUP(K15/(1-Config!$C$5-Config!$C$19-Config!$C$32)*2,0)/2),"") | P15: =IF(AND(AND(A15<>"",N(B15)>0),N(O15)>0),O15*(1-Config!$C$20-Config!$C$32)-K15,"") | Q15: =IF(P15="","",P15+J15) | R15: =IF(P15="","",IF(O15<L15,"PREJUÍZO: abaixo do mínimo",IF(O15<M15,"Atenção: abaixo do sugerido","OK: preço saudável")))
C16: =IF(A16="","",SUMIF(Fichas!$A$4:$A$603,A16,Fichas!$E$4:$E$603)) | G16: =IF(AND(A16<>"",N(B16)>0),C16/B16,"") | H16: =IF(AND(A16<>"",N(B16)>0),N(E16)/60*Config!$C$8/B16,"") | I16: =IF(AND(A16<>"",N(B16)>0),G16+N(D16)+H16,"") | J16: =IF(AND(A16<>"",N(B16)>0),N(F16)/60*Config!$C$4/B16,"") | K16: =IF(AND(A16<>"",N(B16)>0),I16+J16,"") | L16: =IF(AND(A16<>"",N(B16)>0),ROUNDUP(K16/(1-Config!$C$20-Config!$C$32)*10,0)/10,"") | M16: =IF(AND(A16<>"",N(B16)>0),ROUNDUP(K16/(1-Config!$C$5-Config!$C$20-Config!$C$32)*2,0)/2,"") | N16: =IF(AND(A16<>"",N(B16)>0),IF((1-Config!$C$5-Config!$C$19-Config!$C$32)<=0,"MARGEM ALTA DEMAIS",ROUNDUP(K16/(1-Config!$C$5-Config!$C$19-Config!$C$32)*2,0)/2),"") | P16: =IF(AND(AND(A16<>"",N(B16)>0),N(O16)>0),O16*(1-Config!$C$20-Config!$C$32)-K16,"") | Q16: =IF(P16="","",P16+J16) | R16: =IF(P16="","",IF(O16<L16,"PREJUÍZO: abaixo do mínimo",IF(O16<M16,"Atenção: abaixo do sugerido","OK: preço saudável")))
C17: =IF(A17="","",SUMIF(Fichas!$A$4:$A$603,A17,Fichas!$E$4:$E$603)) | G17: =IF(AND(A17<>"",N(B17)>0),C17/B17,"") | H17: =IF(AND(A17<>"",N(B17)>0),N(E17)/60*Config!$C$8/B17,"") | I17: =IF(AND(A17<>"",N(B17)>0),G17+N(D17)+H17,"") | J17: =IF(AND(A17<>"",N(B17)>0),N(F17)/60*Config!$C$4/B17,"") | K17: =IF(AND(A17<>"",N(B17)>0),I17+J17,"") | L17: =IF(AND(A17<>"",N(B17)>0),ROUNDUP(K17/(1-Config!$C$20-Config!$C$32)*10,0)/10,"") | M17: =IF(AND(A17<>"",N(B17)>0),ROUNDUP(K17/(1-Config!$C$5-Config!$C$20-Config!$C$32)*2,0)/2,"") | N17: =IF(AND(A17<>"",N(B17)>0),IF((1-Config!$C$5-Config!$C$19-Config!$C$32)<=0,"MARGEM ALTA DEMAIS",ROUNDUP(K17/(1-Config!$C$5-Config!$C$19-Config!$C$32)*2,0)/2),"") | P17: =IF(AND(AND(A17<>"",N(B17)>0),N(O17)>0),O17*(1-Config!$C$20-Config!$C$32)-K17,"") | Q17: =IF(P17="","",P17+J17) | R17: =IF(P17="","",IF(O17<L17,"PREJUÍZO: abaixo do mínimo",IF(O17<M17,"Atenção: abaixo do sugerido","OK: preço saudável")))
C18: =IF(A18="","",SUMIF(Fichas!$A$4:$A$603,A18,Fichas!$E$4:$E$603)) | G18: =IF(AND(A18<>"",N(B18)>0),C18/B18,"") | H18: =IF(AND(A18<>"",N(B18)>0),N(E18)/60*Config!$C$8/B18,"") | I18: =IF(AND(A18<>"",N(B18)>0),G18+N(D18)+H18,"") | J18: =IF(AND(A18<>"",N(B18)>0),N(F18)/60*Config!$C$4/B18,"") | K18: =IF(AND(A18<>"",N(B18)>0),I18+J18,"") | L18: =IF(AND(A18<>"",N(B18)>0),ROUNDUP(K18/(1-Config!$C$20-Config!$C$32)*10,0)/10,"") | M18: =IF(AND(A18<>"",N(B18)>0),ROUNDUP(K18/(1-Config!$C$5-Config!$C$20-Config!$C$32)*2,0)/2,"") | N18: =IF(AND(A18<>"",N(B18)>0),IF((1-Config!$C$5-Config!$C$19-Config!$C$32)<=0,"MARGEM ALTA DEMAIS",ROUNDUP(K18/(1-Config!$C$5-Config!$C$19-Config!$C$32)*2,0)/2),"") | P18: =IF(AND(AND(A18<>"",N(B18)>0),N(O18)>0),O18*(1-Config!$C$20-Config!$C$32)-K18,"") | Q18: =IF(P18="","",P18+J18) | R18: =IF(P18="","",IF(O18<L18,"PREJUÍZO: abaixo do mínimo",IF(O18<M18,"Atenção: abaixo do sugerido","OK: preço saudável")))
... C53: =IF(A53="","",SUMIF(Fichas!$A$4:$A$603,A53,Fichas!$E$4:$E$603)) | G53: =IF(AND(A53<>"",N(B53)>0),C53/B53,"") | H53: =IF(AND(A53<>"",N(B53)>0),N(E53)/60*Config!$C$8/B53,"") | I53: =IF(AND(A53<>"",N(B53)>0),G53+N(D53)+H53,"") | J53: =IF(AND(A53<>"",N(B53)>0),N(F53)/60*Config!$C$4/B53,"") | K53: =IF(AND(A53<>"",N(B53)>0),I53+J53,"") | L53: =IF(AND(A53<>"",N(B53)>0),ROUNDUP(K53/(1-Config!$C$20-Config!$C$32)*10,0)/10,"") | M53: =IF(AND(A53<>"",N(B53)>0),ROUNDUP(K53/(1-Config!$C$5-Config!$C$20-Config!$C$32)*2,0)/2,"") | N53: =IF(AND(A53<>"",N(B53)>0),IF((1-Config!$C$5-Config!$C$19-Config!$C$32)<=0,"MARGEM ALTA DEMAIS",ROUNDUP(K53/(1-Config!$C$5-Config!$C$19-Config!$C$32)*2,0)/2),"") | P53: =IF(AND(AND(A53<>"",N(B53)>0),N(O53)>0),O53*(1-Config!$C$20-Config!$C$32)-K53,"") | Q53: =IF(P53="","",P53+J53) | R53: =IF(P53="","",IF(O53<L53,"PREJUÍZO: abaixo do mínimo",IF(O53<M53,"Atenção: abaixo do sugerido","OK: preço saudável")))
A55: Como ler: se o SEU PREÇO estiver abaixo do MÍNIMO, cada unidade vendida paga menos que o seu custo (contando a sua hora). Entre o mínimo e o sugerido, você se paga, mas o negócio não guarda reserva.

Sheet Entrega
A1: 5. Entrega por bairro
A2: Distância de IDA (veja no Google Maps). Se paga motoboy, preencha o valor pago e a planilha ignora o cálculo de km.
A3: Bairro / região | B3: Km de ida | C3: Minutos ida + volta | D3: Pago a motoboy (R$) | E3: CUSTO REAL da entrega | F3: TAXA SUGERIDA
A4: Mesmo bairro | B4: 1 | C4: 15 | E4: =IF(A4="","",IF(N(D4)>0,D4,N(B4)*2*Config!$C$12+N(C4)/60*Config!$C$4)) | F4: =IF(E4="","",MAX(2,ROUNDUP(E4*2,0)/2))
A5: Centro | B5: 3.5 | C5: 25 | E5: =IF(A5="","",IF(N(D5)>0,D5,N(B5)*2*Config!$C$12+N(C5)/60*Config!$C$4)) | F5: =IF(E5="","",MAX(2,ROUNDUP(E5*2,0)/2))
A6: Jardim América | B6: 6 | C6: 35 | E6: =IF(A6="","",IF(N(D6)>0,D6,N(B6)*2*Config!$C$12+N(C6)/60*Config!$C$4)) | F6: =IF(E6="","",MAX(2,ROUNDUP(E6*2,0)/2))
A7: Vila Nova (motoboy) | B7: 8 | D7: 12 | E7: =IF(A7="","",IF(N(D7)>0,D7,N(B7)*2*Config!$C$12+N(C7)/60*Config!$C$4)) | F7: =IF(E7="","",MAX(2,ROUNDUP(E7*2,0)/2))
E8: =IF(A8="","",IF(N(D8)>0,D8,N(B8)*2*Config!$C$12+N(C8)/60*Config!$C$4)) | F8: =IF(E8="","",MAX(2,ROUNDUP(E8*2,0)/2))
E9: =IF(A9="","",IF(N(D9)>0,D9,N(B9)*2*Config!$C$12+N(C9)/60*Config!$C$4)) | F9: =IF(E9="","",MAX(2,ROUNDUP(E9*2,0)/2))
E10: =IF(A10="","",IF(N(D10)>0,D10,N(B10)*2*Config!$C$12+N(C10)/60*Config!$C$4)) | F10: =IF(E10="","",MAX(2,ROUNDUP(E10*2,0)/2))
E11: =IF(A11="","",IF(N(D11)>0,D11,N(B11)*2*Config!$C$12+N(C11)/60*Config!$C$4)) | F11: =IF(E11="","",MAX(2,ROUNDUP(E11*2,0)/2))
E12: =IF(A12="","",IF(N(D12)>0,D12,N(B12)*2*Config!$C$12+N(C12)/60*Config!$C$4)) | F12: =IF(E12="","",MAX(2,ROUNDUP(E12*2,0)/2))
E13: =IF(A13="","",IF(N(D13)>0,D13,N(B13)*2*Config!$C$12+N(C13)/60*Config!$C$4)) | F13: =IF(E13="","",MAX(2,ROUNDUP(E13*2,0)/2))
E14: =IF(A14="","",IF(N(D14)>0,D14,N(B14)*2*Config!$C$12+N(C14)/60*Config!$C$4)) | F14: =IF(E14="","",MAX(2,ROUNDUP(E14*2,0)/2))
E15: =IF(A15="","",IF(N(D15)>0,D15,N(B15)*2*Config!$C$12+N(C15)/60*Config!$C$4)) | F15: =IF(E15="","",MAX(2,ROUNDUP(E15*2,0)/2))
E16: =IF(A16="","",IF(N(D16)>0,D16,N(B16)*2*Config!$C$12+N(C16)/60*Config!$C$4)) | F16: =IF(E16="","",MAX(2,ROUNDUP(E16*2,0)/2))
E17: =IF(A17="","",IF(N(D17)>0,D17,N(B17)*2*Config!$C$12+N(C17)/60*Config!$C$4)) | F17: =IF(E17="","",MAX(2,ROUNDUP(E17*2,0)/2))
E18: =IF(A18="","",IF(N(D18)>0,D18,N(B18)*2*Config!$C$12+N(C18)/60*Config!$C$4)) | F18: =IF(E18="","",MAX(2,ROUNDUP(E18*2,0)/2))
E19: =IF(A19="","",IF(N(D19)>0,D19,N(B19)*2*Config!$C$12+N(C19)/60*Config!$C$4)) | F19: =IF(E19="","",MAX(2,ROUNDUP(E19*2,0)/2))
... E43: =IF(A43="","",IF(N(D43)>0,D43,N(B43)*2*Config!$C$12+N(C43)/60*Config!$C$4)) | F43: =IF(E43="","",MAX(2,ROUNDUP(E43*2,0)/2))
A45: A taxa sugerida cobre combustível, desgaste e o SEU tempo no trânsito (com o valor da sua hora). Arredonda para cima de R$ 0,50 em R$ 0,50, com mínimo de R$ 2.

Sheet Pedidos
A1: 6. Pedidos
A2: Uma linha por pedido. Preencha as colunas amarelas. Se o 'Preço unitário' ficar vazio, a planilha usa o 'Seu preço atual' da aba Produtos.
A3: Data | B3: Cliente | C3: Produto | D3: Qtd | E3: Preço unitário cobrado (vazio = tabela) | F3: Bairro (entrega) | G3: Taxa de entrega cobrada | H3: Pagamento | I3: Status | J3: Sinal recebido (R$) | K3: TOTAL do pedido | L3: Taxa da operadora | M3: Custo de material | N3: Sua hora (custo) | O3: Custo da entrega | P3: LUCRO do pedido | Q3: Falta receber | R3: Mês | S3: Ano
A4: 46297 | B4: Ana (vizinha) | C4: Marmita frango grelhado | D4: 5 | F4: Mesmo bairro | G4: 0 | H4: Pix | I4: Entregue | J4: 0 | K4: =IF(AND(C4<>"",N(D4)>0,I4<>"Cancelado"),D4*IF(N(E4)>0,E4,IFERROR(VLOOKUP(C4,Produtos!$A$4:$O$53,15,0),0))+N(G4),"") | L4: =IF(K4="","",K4*IFERROR(VLOOKUP(H4,Config!$B$15:$C$19,2,0),0)) | M4: =IF(K4="","",D4*IFERROR(VLOOKUP(C4,Produtos!$A$4:$I$53,9,0),0)) | N4: =IF(K4="","",D4*IFERROR(VLOOKUP(C4,Produtos!$A$4:$J$53,10,0),0)) | O4: =IF(OR(K4="",F4=""),IF(K4="","",0),IFERROR(VLOOKUP(F4,Entrega!$A$4:$E$43,5,0),0)) | P4: =IF(K4="","",K4-L4-M4-N4-O4) | Q4: =IF(K4="","",IF(I4="Entregue",0,K4-N(J4))) | R4: =IF(ISNUMBER(A4),MONTH(A4),"") | S4: =IF(ISNUMBER(A4),YEAR(A4),"")
A5: 46298 | B5: Escritório Silva | C5: Marmita frango grelhado | D5: 8 | E5: 21 | F5: Centro | G5: 6 | H5: Pix | I5: Entregue | J5: 0 | K5: =IF(AND(C5<>"",N(D5)>0,I5<>"Cancelado"),D5*IF(N(E5)>0,E5,IFERROR(VLOOKUP(C5,Produtos!$A$4:$O$53,15,0),0))+N(G5),"") | L5: =IF(K5="","",K5*IFERROR(VLOOKUP(H5,Config!$B$15:$C$19,2,0),0)) | M5: =IF(K5="","",D5*IFERROR(VLOOKUP(C5,Produtos!$A$4:$I$53,9,0),0)) | N5: =IF(K5="","",D5*IFERROR(VLOOKUP(C5,Produtos!$A$4:$J$53,10,0),0)) | O5: =IF(OR(K5="",F5=""),IF(K5="","",0),IFERROR(VLOOKUP(F5,Entrega!$A$4:$E$43,5,0),0)) | P5: =IF(K5="","",K5-L5-M5-N5-O5) | Q5: =IF(K5="","",IF(I5="Entregue",0,K5-N(J5))) | R5: =IF(ISNUMBER(A5),MONTH(A5),"") | S5: =IF(ISNUMBER(A5),YEAR(A5),"")
A6: 46300 | B6: Festa Júlia | C6: Coxinha de frango (unid.) | D6: 100 | E6: 1.8 | F6: Jardim América | G6: 8 | H6: Pix | I6: Entregue | J6: 90 | K6: =IF(AND(C6<>"",N(D6)>0,I6<>"Cancelado"),D6*IF(N(E6)>0,E6,IFERROR(VLOOKUP(C6,Produtos!$A$4:$O$53,15,0),0))+N(G6),"") | L6: =IF(K6="","",K6*IFERROR(VLOOKUP(H6,Config!$B$15:$C$19,2,0),0)) | M6: =IF(K6="","",D6*IFERROR(VLOOKUP(C6,Produtos!$A$4:$I$53,9,0),0)) | N6: =IF(K6="","",D6*IFERROR(VLOOKUP(C6,Produtos!$A$4:$J$53,10,0),0)) | O6: =IF(OR(K6="",F6=""),IF(K6="","",0),IFERROR(VLOOKUP(F6,Entrega!$A$4:$E$43,5,0),0)) | P6: =IF(K6="","",K6-L6-M6-N6-O6) | Q6: =IF(K6="","",IF(I6="Entregue",0,K6-N(J6))) | R6: =IF(ISNUMBER(A6),MONTH(A6),"") | S6: =IF(ISNUMBER(A6),YEAR(A6),"")
A7: 46301 | B7: Marcos | C7: Marmita frango grelhado | D7: 2 | F7: Mesmo bairro | G7: 3 | H7: Cartão de crédito | I7: Entregue | J7: 0 | K7: =IF(AND(C7<>"",N(D7)>0,I7<>"Cancelado"),D7*IF(N(E7)>0,E7,IFERROR(VLOOKUP(C7,Produtos!$A$4:$O$53,15,0),0))+N(G7),"") | L7: =IF(K7="","",K7*IFERROR(VLOOKUP(H7,Config!$B$15:$C$19,2,0),0)) | M7: =IF(K7="","",D7*IFERROR(VLOOKUP(C7,Produtos!$A$4:$I$53,9,0),0)) | N7: =IF(K7="","",D7*IFERROR(VLOOKUP(C7,Produtos!$A$4:$J$53,10,0),0)) | O7: =IF(OR(K7="",F7=""),IF(K7="","",0),IFERROR(VLOOKUP(F7,Entrega!$A$4:$E$43,5,0),0)) | P7: =IF(K7="","",K7-L7-M7-N7-O7) | Q7: =IF(K7="","",IF(I7="Entregue",0,K7-N(J7))) | R7: =IF(ISNUMBER(A7),MONTH(A7),"") | S7: =IF(ISNUMBER(A7),YEAR(A7),"")
A8: 46303 | B8: Festa Júlia | C8: Brigadeiro gourmet (unid.) | D8: 80 | F8: Jardim América | G8: 0 | H8: Pix | I8: Entregue | J8: 100 | K8: =IF(AND(C8<>"",N(D8)>0,I8<>"Cancelado"),D8*IF(N(E8)>0,E8,IFERROR(VLOOKUP(C8,Produtos!$A$4:$O$53,15,0),0))+N(G8),"") | L8: =IF(K8="","",K8*IFERROR(VLOOKUP(H8,Config!$B$15:$C$19,2,0),0)) | M8: =IF(K8="","",D8*IFERROR(VLOOKUP(C8,Produtos!$A$4:$I$53,9,0),0)) | N8: =IF(K8="","",D8*IFERROR(VLOOKUP(C8,Produtos!$A$4:$J$53,10,0),0)) | O8: =IF(OR(K8="",F8=""),IF(K8="","",0),IFERROR(VLOOKUP(F8,Entrega!$A$4:$E$43,5,0),0)) | P8: =IF(K8="","",K8-L8-M8-N8-O8) | Q8: =IF(K8="","",IF(I8="Entregue",0,K8-N(J8))) | R8: =IF(ISNUMBER(A8),MONTH(A8),"") | S8: =IF(ISNUMBER(A8),YEAR(A8),"")
A9: 46305 | B9: Bruna | C9: Marmita frango grelhado | D9: 10 | E9: 20 | F9: Vila Nova (motoboy) | G9: 12 | H9: Pix | I9: Entregue | J9: 0 | K9: =IF(AND(C9<>"",N(D9)>0,I9<>"Cancelado"),D9*IF(N(E9)>0,E9,IFERROR(VLOOKUP(C9,Produtos!$A$4:$O$53,15,0),0))+N(G9),"") | L9: =IF(K9="","",K9*IFERROR(VLOOKUP(H9,Config!$B$15:$C$19,2,0),0)) | M9: =IF(K9="","",D9*IFERROR(VLOOKUP(C9,Produtos!$A$4:$I$53,9,0),0)) | N9: =IF(K9="","",D9*IFERROR(VLOOKUP(C9,Produtos!$A$4:$J$53,10,0),0)) | O9: =IF(OR(K9="",F9=""),IF(K9="","",0),IFERROR(VLOOKUP(F9,Entrega!$A$4:$E$43,5,0),0)) | P9: =IF(K9="","",K9-L9-M9-N9-O9) | Q9: =IF(K9="","",IF(I9="Entregue",0,K9-N(J9))) | R9: =IF(ISNUMBER(A9),MONTH(A9),"") | S9: =IF(ISNUMBER(A9),YEAR(A9),"")
A10: 46307 | B10: Igreja | C10: Coxinha de frango (unid.) | D10: 200 | E10: 1.6 | F10: Centro | G10: 0 | H10: Dinheiro | I10: Entregue | J10: 160 | K10: =IF(AND(C10<>"",N(D10)>0,I10<>"Cancelado"),D10*IF(N(E10)>0,E10,IFERROR(VLOOKUP(C10,Produtos!$A$4:$O$53,15,0),0))+N(G10),"") | L10: =IF(K10="","",K10*IFERROR(VLOOKUP(H10,Config!$B$15:$C$19,2,0),0)) | M10: =IF(K10="","",D10*IFERROR(VLOOKUP(C10,Produtos!$A$4:$I$53,9,0),0)) | N10: =IF(K10="","",D10*IFERROR(VLOOKUP(C10,Produtos!$A$4:$J$53,10,0),0)) | O10: =IF(OR(K10="",F10=""),IF(K10="","",0),IFERROR(VLOOKUP(F10,Entrega!$A$4:$E$43,5,0),0)) | P10: =IF(K10="","",K10-L10-M10-N10-O10) | Q10: =IF(K10="","",IF(I10="Entregue",0,K10-N(J10))) | R10: =IF(ISNUMBER(A10),MONTH(A10),"") | S10: =IF(ISNUMBER(A10),YEAR(A10),"")
A11: 46310 | B11: iFood | C11: Marmita frango grelhado | D11: 6 | E11: 26 | G11: 0 | H11: App de delivery | I11: Entregue | J11: 0 | K11: =IF(AND(C11<>"",N(D11)>0,I11<>"Cancelado"),D11*IF(N(E11)>0,E11,IFERROR(VLOOKUP(C11,Produtos!$A$4:$O$53,15,0),0))+N(G11),"") | L11: =IF(K11="","",K11*IFERROR(VLOOKUP(H11,Config!$B$15:$C$19,2,0),0)) | M11: =IF(K11="","",D11*IFERROR(VLOOKUP(C11,Produtos!$A$4:$I$53,9,0),0)) | N11: =IF(K11="","",D11*IFERROR(VLOOKUP(C11,Produtos!$A$4:$J$53,10,0),0)) | O11: =IF(OR(K11="",F11=""),IF(K11="","",0),IFERROR(VLOOKUP(F11,Entrega!$A$4:$E$43,5,0),0)) | P11: =IF(K11="","",K11-L11-M11-N11-O11) | Q11: =IF(K11="","",IF(I11="Entregue",0,K11-N(J11))) | R11: =IF(ISNUMBER(A11),MONTH(A11),"") | S11: =IF(ISNUMBER(A11),YEAR(A11),"")
A12: 46312 | B12: Carla | C12: Brigadeiro gourmet (unid.) | D12: 40 | F12: Centro | G12: 6 | H12: Cartão de débito | I12: Entregue | J12: 0 | K12: =IF(AND(C12<>"",N(D12)>0,I12<>"Cancelado"),D12*IF(N(E12)>0,E12,IFERROR(VLOOKUP(C12,Produtos!$A$4:$O$53,15,0),0))+N(G12),"") | L12: =IF(K12="","",K12*IFERROR(VLOOKUP(H12,Config!$B$15:$C$19,2,0),0)) | M12: =IF(K12="","",D12*IFERROR(VLOOKUP(C12,Produtos!$A$4:$I$53,9,0),0)) | N12: =IF(K12="","",D12*IFERROR(VLOOKUP(C12,Produtos!$A$4:$J$53,10,0),0)) | O12: =IF(OR(K12="",F12=""),IF(K12="","",0),IFERROR(VLOOKUP(F12,Entrega!$A$4:$E$43,5,0),0)) | P12: =IF(K12="","",K12-L12-M12-N12-O12) | Q12: =IF(K12="","",IF(I12="Entregue",0,K12-N(J12))) | R12: =IF(ISNUMBER(A12),MONTH(A12),"") | S12: =IF(ISNUMBER(A12),YEAR(A12),"")
A13: 46317 | B13: Aniversário Léo | C13: Coxinha de frango (unid.) | D13: 150 | F13: Jardim América | G13: 8 | H13: Pix | I13: Sinal pago | J13: 150 | K13: =IF(AND(C13<>"",N(D13)>0,I13<>"Cancelado"),D13*IF(N(E13)>0,E13,IFERROR(VLOOKUP(C13,Produtos!$A$4:$O$53,15,0),0))+N(G13),"") | L13: =IF(K13="","",K13*IFERROR(VLOOKUP(H13,Config!$B$15:$C$19,2,0),0)) | M13: =IF(K13="","",D13*IFERROR(VLOOKUP(C13,Produtos!$A$4:$I$53,9,0),0)) | N13: =IF(K13="","",D13*IFERROR(VLOOKUP(C13,Produtos!$A$4:$J$53,10,0),0)) | O13: =IF(OR(K13="",F13=""),IF(K13="","",0),IFERROR(VLOOKUP(F13,Entrega!$A$4:$E$43,5,0),0)) | P13: =IF(K13="","",K13-L13-M13-N13-O13) | Q13: =IF(K13="","",IF(I13="Entregue",0,K13-N(J13))) | R13: =IF(ISNUMBER(A13),MONTH(A13),"") | S13: =IF(ISNUMBER(A13),YEAR(A13),"")
A14: 46318 | B14: Escritório Silva | C14: Marmita frango grelhado | D14: 8 | E14: 21 | F14: Centro | G14: 6 | H14: Pix | I14: Encomenda | J14: 0 | K14: =IF(AND(C14<>"",N(D14)>0,I14<>"Cancelado"),D14*IF(N(E14)>0,E14,IFERROR(VLOOKUP(C14,Produtos!$A$4:$O$53,15,0),0))+N(G14),"") | L14: =IF(K14="","",K14*IFERROR(VLOOKUP(H14,Config!$B$15:$C$19,2,0),0)) | M14: =IF(K14="","",D14*IFERROR(VLOOKUP(C14,Produtos!$A$4:$I$53,9,0),0)) | N14: =IF(K14="","",D14*IFERROR(VLOOKUP(C14,Produtos!$A$4:$J$53,10,0),0)) | O14: =IF(OR(K14="",F14=""),IF(K14="","",0),IFERROR(VLOOKUP(F14,Entrega!$A$4:$E$43,5,0),0)) | P14: =IF(K14="","",K14-L14-M14-N14-O14) | Q14: =IF(K14="","",IF(I14="Entregue",0,K14-N(J14))) | R14: =IF(ISNUMBER(A14),MONTH(A14),"") | S14: =IF(ISNUMBER(A14),YEAR(A14),"")
K15: =IF(AND(C15<>"",N(D15)>0,I15<>"Cancelado"),D15*IF(N(E15)>0,E15,IFERROR(VLOOKUP(C15,Produtos!$A$4:$O$53,15,0),0))+N(G15),"") | L15: =IF(K15="","",K15*IFERROR(VLOOKUP(H15,Config!$B$15:$C$19,2,0),0)) | M15: =IF(K15="","",D15*IFERROR(VLOOKUP(C15,Produtos!$A$4:$I$53,9,0),0)) | N15: =IF(K15="","",D15*IFERROR(VLOOKUP(C15,Produtos!$A$4:$J$53,10,0),0)) | O15: =IF(OR(K15="",F15=""),IF(K15="","",0),IFERROR(VLOOKUP(F15,Entrega!$A$4:$E$43,5,0),0)) | P15: =IF(K15="","",K15-L15-M15-N15-O15) | Q15: =IF(K15="","",IF(I15="Entregue",0,K15-N(J15))) | R15: =IF(ISNUMBER(A15),MONTH(A15),"") | S15: =IF(ISNUMBER(A15),YEAR(A15),"")
K16: =IF(AND(C16<>"",N(D16)>0,I16<>"Cancelado"),D16*IF(N(E16)>0,E16,IFERROR(VLOOKUP(C16,Produtos!$A$4:$O$53,15,0),0))+N(G16),"") | L16: =IF(K16="","",K16*IFERROR(VLOOKUP(H16,Config!$B$15:$C$19,2,0),0)) | M16: =IF(K16="","",D16*IFERROR(VLOOKUP(C16,Produtos!$A$4:$I$53,9,0),0)) | N16: =IF(K16="","",D16*IFERROR(VLOOKUP(C16,Produtos!$A$4:$J$53,10,0),0)) | O16: =IF(OR(K16="",F16=""),IF(K16="","",0),IFERROR(VLOOKUP(F16,Entrega!$A$4:$E$43,5,0),0)) | P16: =IF(K16="","",K16-L16-M16-N16-O16) | Q16: =IF(K16="","",IF(I16="Entregue",0,K16-N(J16))) | R16: =IF(ISNUMBER(A16),MONTH(A16),"") | S16: =IF(ISNUMBER(A16),YEAR(A16),"")
K17: =IF(AND(C17<>"",N(D17)>0,I17<>"Cancelado"),D17*IF(N(E17)>0,E17,IFERROR(VLOOKUP(C17,Produtos!$A$4:$O$53,15,0),0))+N(G17),"") | L17: =IF(K17="","",K17*IFERROR(VLOOKUP(H17,Config!$B$15:$C$19,2,0),0)) | M17: =IF(K17="","",D17*IFERROR(VLOOKUP(C17,Produtos!$A$4:$I$53,9,0),0)) | N17: =IF(K17="","",D17*IFERROR(VLOOKUP(C17,Produtos!$A$4:$J$53,10,0),0)) | O17: =IF(OR(K17="",F17=""),IF(K17="","",0),IFERROR(VLOOKUP(F17,Entrega!$A$4:$E$43,5,0),0)) | P17: =IF(K17="","",K17-L17-M17-N17-O17) | Q17: =IF(K17="","",IF(I17="Entregue",0,K17-N(J17))) | R17: =IF(ISNUMBER(A17),MONTH(A17),"") | S17: =IF(ISNUMBER(A17),YEAR(A17),"")
K18: =IF(AND(C18<>"",N(D18)>0,I18<>"Cancelado"),D18*IF(N(E18)>0,E18,IFERROR(VLOOKUP(C18,Produtos!$A$4:$O$53,15,0),0))+N(G18),"") | L18: =IF(K18="","",K18*IFERROR(VLOOKUP(H18,Config!$B$15:$C$19,2,0),0)) | M18: =IF(K18="","",D18*IFERROR(VLOOKUP(C18,Produtos!$A$4:$I$53,9,0),0)) | N18: =IF(K18="","",D18*IFERROR(VLOOKUP(C18,Produtos!$A$4:$J$53,10,0),0)) | O18: =IF(OR(K18="",F18=""),IF(K18="","",0),IFERROR(VLOOKUP(F18,Entrega!$A$4:$E$43,5,0),0)) | P18: =IF(K18="","",K18-L18-M18-N18-O18) | Q18: =IF(K18="","",IF(I18="Entregue",0,K18-N(J18))) | R18: =IF(ISNUMBER(A18),MONTH(A18),"") | S18: =IF(ISNUMBER(A18),YEAR(A18),"")
K19: =IF(AND(C19<>"",N(D19)>0,I19<>"Cancelado"),D19*IF(N(E19)>0,E19,IFERROR(VLOOKUP(C19,Produtos!$A$4:$O$53,15,0),0))+N(G19),"") | L19: =IF(K19="","",K19*IFERROR(VLOOKUP(H19,Config!$B$15:$C$19,2,0),0)) | M19: =IF(K19="","",D19*IFERROR(VLOOKUP(C19,Produtos!$A$4:$I$53,9,0),0)) | N19: =IF(K19="","",D19*IFERROR(VLOOKUP(C19,Produtos!$A$4:$J$53,10,0),0)) | O19: =IF(OR(K19="",F19=""),IF(K19="","",0),IFERROR(VLOOKUP(F19,Entrega!$A$4:$E$43,5,0),0)) | P19: =IF(K19="","",K19-L19-M19-N19-O19) | Q19: =IF(K19="","",IF(I19="Entregue",0,K19-N(J19))) | R19: =IF(ISNUMBER(A19),MONTH(A19),"") | S19: =IF(ISNUMBER(A19),YEAR(A19),"")
K20: =IF(AND(C20<>"",N(D20)>0,I20<>"Cancelado"),D20*IF(N(E20)>0,E20,IFERROR(VLOOKUP(C20,Produtos!$A$4:$O$53,15,0),0))+N(G20),"") | L20: =IF(K20="","",K20*IFERROR(VLOOKUP(H20,Config!$B$15:$C$19,2,0),0)) | M20: =IF(K20="","",D20*IFERROR(VLOOKUP(C20,Produtos!$A$4:$I$53,9,0),0)) | N20: =IF(K20="","",D20*IFERROR(VLOOKUP(C20,Produtos!$A$4:$J$53,10,0),0)) | O20: =IF(OR(K20="",F20=""),IF(K20="","",0),IFERROR(VLOOKUP(F20,Entrega!$A$4:$E$43,5,0),0)) | P20: =IF(K20="","",K20-L20-M20-N20-O20) | Q20: =IF(K20="","",IF(I20="Entregue",0,K20-N(J20))) | R20: =IF(ISNUMBER(A20),MONTH(A20),"") | S20: =IF(ISNUMBER(A20),YEAR(A20),"")
K21: =IF(AND(C21<>"",N(D21)>0,I21<>"Cancelado"),D21*IF(N(E21)>0,E21,IFERROR(VLOOKUP(C21,Produtos!$A$4:$O$53,15,0),0))+N(G21),"") | L21: =IF(K21="","",K21*IFERROR(VLOOKUP(H21,Config!$B$15:$C$19,2,0),0)) | M21: =IF(K21="","",D21*IFERROR(VLOOKUP(C21,Produtos!$A$4:$I$53,9,0),0)) | N21: =IF(K21="","",D21*IFERROR(VLOOKUP(C21,Produtos!$A$4:$J$53,10,0),0)) | O21: =IF(OR(K21="",F21=""),IF(K21="","",0),IFERROR(VLOOKUP(F21,Entrega!$A$4:$E$43,5,0),0)) | P21: =IF(K21="","",K21-L21-M21-N21-O21) | Q21: =IF(K21="","",IF(I21="Entregue",0,K21-N(J21))) | R21: =IF(ISNUMBER(A21),MONTH(A21),"") | S21: =IF(ISNUMBER(A21),YEAR(A21),"")
K22: =IF(AND(C22<>"",N(D22)>0,I22<>"Cancelado"),D22*IF(N(E22)>0,E22,IFERROR(VLOOKUP(C22,Produtos!$A$4:$O$53,15,0),0))+N(G22),"") | L22: =IF(K22="","",K22*IFERROR(VLOOKUP(H22,Config!$B$15:$C$19,2,0),0)) | M22: =IF(K22="","",D22*IFERROR(VLOOKUP(C22,Produtos!$A$4:$I$53,9,0),0)) | N22: =IF(K22="","",D22*IFERROR(VLOOKUP(C22,Produtos!$A$4:$J$53,10,0),0)) | O22: =IF(OR(K22="",F22=""),IF(K22="","",0),IFERROR(VLOOKUP(F22,Entrega!$A$4:$E$43,5,0),0)) | P22: =IF(K22="","",K22-L22-M22-N22-O22) | Q22: =IF(K22="","",IF(I22="Entregue",0,K22-N(J22))) | R22: =IF(ISNUMBER(A22),MONTH(A22),"") | S22: =IF(ISNUMBER(A22),YEAR(A22),"")
K23: =IF(AND(C23<>"",N(D23)>0,I23<>"Cancelado"),D23*IF(N(E23)>0,E23,IFERROR(VLOOKUP(C23,Produtos!$A$4:$O$53,15,0),0))+N(G23),"") | L23: =IF(K23="","",K23*IFERROR(VLOOKUP(H23,Config!$B$15:$C$19,2,0),0)) | M23: =IF(K23="","",D23*IFERROR(VLOOKUP(C23,Produtos!$A$4:$I$53,9,0),0)) | N23: =IF(K23="","",D23*IFERROR(VLOOKUP(C23,Produtos!$A$4:$J$53,10,0),0)) | O23: =IF(OR(K23="",F23=""),IF(K23="","",0),IFERROR(VLOOKUP(F23,Entrega!$A$4:$E$43,5,0),0)) | P23: =IF(K23="","",K23-L23-M23-N23-O23) | Q23: =IF(K23="","",IF(I23="Entregue",0,K23-N(J23))) | R23: =IF(ISNUMBER(A23),MONTH(A23),"") | S23: =IF(ISNUMBER(A23),YEAR(A23),"")
K24: =IF(AND(C24<>"",N(D24)>0,I24<>"Cancelado"),D24*IF(N(E24)>0,E24,IFERROR(VLOOKUP(C24,Produtos!$A$4:$O$53,15,0),0))+N(G24),"") | L24: =IF(K24="","",K24*IFERROR(VLOOKUP(H24,Config!$B$15:$C$19,2,0),0)) | M24: =IF(K24="","",D24*IFERROR(VLOOKUP(C24,Produtos!$A$4:$I$53,9,0),0)) | N24: =IF(K24="","",D24*IFERROR(VLOOKUP(C24,Produtos!$A$4:$J$53,10,0),0)) | O24: =IF(OR(K24="",F24=""),IF(K24="","",0),IFERROR(VLOOKUP(F24,Entrega!$A$4:$E$43,5,0),0)) | P24: =IF(K24="","",K24-L24-M24-N24-O24) | Q24: =IF(K24="","",IF(I24="Entregue",0,K24-N(J24))) | R24: =IF(ISNUMBER(A24),MONTH(A24),"") | S24: =IF(ISNUMBER(A24),YEAR(A24),"")
K25: =IF(AND(C25<>"",N(D25)>0,I25<>"Cancelado"),D25*IF(N(E25)>0,E25,IFERROR(VLOOKUP(C25,Produtos!$A$4:$O$53,15,0),0))+N(G25),"") | L25: =IF(K25="","",K25*IFERROR(VLOOKUP(H25,Config!$B$15:$C$19,2,0),0)) | M25: =IF(K25="","",D25*IFERROR(VLOOKUP(C25,Produtos!$A$4:$I$53,9,0),0)) | N25: =IF(K25="","",D25*IFERROR(VLOOKUP(C25,Produtos!$A$4:$J$53,10,0),0)) | O25: =IF(OR(K25="",F25=""),IF(K25="","",0),IFERROR(VLOOKUP(F25,Entrega!$A$4:$E$43,5,0),0)) | P25: =IF(K25="","",K25-L25-M25-N25-O25) | Q25: =IF(K25="","",IF(I25="Entregue",0,K25-N(J25))) | R25: =IF(ISNUMBER(A25),MONTH(A25),"") | S25: =IF(ISNUMBER(A25),YEAR(A25),"")
