Workbook

Sheet Leia primeiro
A1: Painel das Primeiras Vendas
A3: O QUE ESTE PAINEL FAZ
A4: Mostra, sem você fazer contas, quantas pessoas avançam em cada etapa da venda, por semana e por canal; quanto dinheiro realmente sobra depois de custos e taxas; e qual etapa está travando.
A5: ORDEM DE USO:
A6: 1. Configurações: preencha a data de início, suas taxas e a meta de atividade semanal.
A7: 2. Contatos: registre cada pessoa (uma linha) e atualize a etapa sempre que ela avançar.
A8: 3. Vendas e custos: lance cada venda e cada gasto (material, frete, impulsionamento, ferramentas).
A9: 4. Tempo: anote os minutos dedicados por dia. Serve para calcular quanto vale sua hora de verdade.
A10: 5. Painel: leia os números e o diagnóstico automático toda semana.
A11: Células em bege: você preenche. Células em azul-claro: calculadas. Não apague as fórmulas.
A12: IMPORTANTE:
A13: Visualizações, curtidas e seguidores não entram aqui de propósito. Eles medem alcance, não vendas. O painel mede pessoas que conversaram com você e dinheiro que entrou.
... A15: Nenhum número vem preenchido. O arquivo Painel-EXEMPLO-dados-ficticios.xlsx mostra o painel funcionando com dados inventados, só para você ver como fica.

Sheet Configurações
A1: Configurações
A2: Preencha uma vez e atualize quando algo mudar.
A4: Item | B4: Valor | C4: Observação
A5: Data de início | C5: As semanas são contadas a partir desta data
A6: Taxa percentual do meio de pagamento principal | C6: Ex.: 8,99% numa plataforma de produto digital; 0% em Pix para pessoa física. Confira no site oficial
A7: Taxa fixa por venda (R$) | C7: Valor fixo cobrado por transação, se houver
A8: Imposto estimado sobre a receita (%) | C8: Se você é MEI, o imposto é fixo mensal: lance em Custos e deixe 0% aqui
A9: Meta semanal de novos contatos | B9: 30 | C9: Meta de atividade, não de faturamento
A10: Meta semanal de conteúdos publicados | B10: 3
A11: Valor de referência da sua hora (R$) | C11: Usado para comparar com o que você realmente ganhou por hora
A14: Canais (edite os nomes se quiser)
A15: Rede próxima
A16: Indicação
A17: Comunidade
A18: Contato direto
A19: TikTok
A20: Instagram
A21: WhatsApp
A22: Outro

Sheet Contatos
A1: Contatos
A2: Uma linha por pessoa. Etapa = o ponto mais avançado a que a pessoa chegou. Perdido = disse não ou não respondeu aos dois acompanhamentos.
A4: Data do 1º contato | B4: Semana | C4: Nome | D4: Canal | E4: Origem (post, grupo, indicação de quem) | F4: Etapa atual | G4: Nº da etapa | H4: Perdido? | I4: Motivo da perda | J4: Próxima ação | K4: Data da próxima ação
B5: =IF(OR(A5="",Configurações!$B$5=""),"",INT((A5-Configurações!$B$5)/7)+1) | G5: =IF(F5="","",VALUE(LEFT(F5,1)))
B6: =IF(OR(A6="",Configurações!$B$5=""),"",INT((A6-Configurações!$B$5)/7)+1) | G6: =IF(F6="","",VALUE(LEFT(F6,1)))
B7: =IF(OR(A7="",Configurações!$B$5=""),"",INT((A7-Configurações!$B$5)/7)+1) | G7: =IF(F7="","",VALUE(LEFT(F7,1)))
B8: =IF(OR(A8="",Configurações!$B$5=""),"",INT((A8-Configurações!$B$5)/7)+1) | G8: =IF(F8="","",VALUE(LEFT(F8,1)))
B9: =IF(OR(A9="",Configurações!$B$5=""),"",INT((A9-Configurações!$B$5)/7)+1) | G9: =IF(F9="","",VALUE(LEFT(F9,1)))
B10: =IF(OR(A10="",Configurações!$B$5=""),"",INT((A10-Configurações!$B$5)/7)+1) | G10: =IF(F10="","",VALUE(LEFT(F10,1)))
B11: =IF(OR(A11="",Configurações!$B$5=""),"",INT((A11-Configurações!$B$5)/7)+1) | G11: =IF(F11="","",VALUE(LEFT(F11,1)))
B12: =IF(OR(A12="",Configurações!$B$5=""),"",INT((A12-Configurações!$B$5)/7)+1) | G12: =IF(F12="","",VALUE(LEFT(F12,1)))
B13: =IF(OR(A13="",Configurações!$B$5=""),"",INT((A13-Configurações!$B$5)/7)+1) | G13: =IF(F13="","",VALUE(LEFT(F13,1)))
B14: =IF(OR(A14="",Configurações!$B$5=""),"",INT((A14-Configurações!$B$5)/7)+1) | G14: =IF(F14="","",VALUE(LEFT(F14,1)))
B15: =IF(OR(A15="",Configurações!$B$5=""),"",INT((A15-Configurações!$B$5)/7)+1) | G15: =IF(F15="","",VALUE(LEFT(F15,1)))
B16: =IF(OR(A16="",Configurações!$B$5=""),"",INT((A16-Configurações!$B$5)/7)+1) | G16: =IF(F16="","",VALUE(LEFT(F16,1)))
... B504: =IF(OR(A504="",Configurações!$B$5=""),"",INT((A504-Configurações!$B$5)/7)+1) | G504: =IF(F504="","",VALUE(LEFT(F504,1)))

Sheet Vendas e custos
A1: Vendas e custos
A2: Lance cada venda à esquerda e cada gasto à direita. As taxas são calculadas com o que está em Configurações.
A4: Data | B4: Semana | C4: Cliente | D4: Canal | E4: O que vendeu | F4: Valor (R$) | G4: Custo direto (R$) | H4: Taxas (R$) | I4: Imposto (R$) | J4: Reembolsado? | K4: Sobra (R$) | M4: Data | N4: Semana | O4: Gasto | P4: Categoria | Q4: Valor (R$)
B5: =IF(OR(A5="",Configurações!$B$5=""),"",INT((A5-Configurações!$B$5)/7)+1) | H5: =IF(F5="","",F5*Configurações!$B$6+Configurações!$B$7) | I5: =IF(F5="","",F5*Configurações!$B$8) | K5: =IF(F5="","",IF(J5="Sim",-H5-G5,F5-G5-H5-I5)) | N5: =IF(OR(M5="",Configurações!$B$5=""),"",INT((M5-Configurações!$B$5)/7)+1)
B6: =IF(OR(A6="",Configurações!$B$5=""),"",INT((A6-Configurações!$B$5)/7)+1) | H6: =IF(F6="","",F6*Configurações!$B$6+Configurações!$B$7) | I6: =IF(F6="","",F6*Configurações!$B$8) | K6: =IF(F6="","",IF(J6="Sim",-H6-G6,F6-G6-H6-I6)) | N6: =IF(OR(M6="",Configurações!$B$5=""),"",INT((M6-Configurações!$B$5)/7)+1)
B7: =IF(OR(A7="",Configurações!$B$5=""),"",INT((A7-Configurações!$B$5)/7)+1) | H7: =IF(F7="","",F7*Configurações!$B$6+Configurações!$B$7) | I7: =IF(F7="","",F7*Configurações!$B$8) | K7: =IF(F7="","",IF(J7="Sim",-H7-G7,F7-G7-H7-I7)) | N7: =IF(OR(M7="",Configurações!$B$5=""),"",INT((M7-Configurações!$B$5)/7)+1)
B8: =IF(OR(A8="",Configurações!$B$5=""),"",INT((A8-Configurações!$B$5)/7)+1) | H8: =IF(F8="","",F8*Configurações!$B$6+Configurações!$B$7) | I8: =IF(F8="","",F8*Configurações!$B$8) | K8: =IF(F8="","",IF(J8="Sim",-H8-G8,F8-G8-H8-I8)) | N8: =IF(OR(M8="",Configurações!$B$5=""),"",INT((M8-Configurações!$B$5)/7)+1)
B9: =IF(OR(A9="",Configurações!$B$5=""),"",INT((A9-Configurações!$B$5)/7)+1) | H9: =IF(F9="","",F9*Configurações!$B$6+Configurações!$B$7) | I9: =IF(F9="","",F9*Configurações!$B$8) | K9: =IF(F9="","",IF(J9="Sim",-H9-G9,F9-G9-H9-I9)) | N9: =IF(OR(M9="",Configurações!$B$5=""),"",INT((M9-Configurações!$B$5)/7)+1)
B10: =IF(OR(A10="",Configurações!$B$5=""),"",INT((A10-Configurações!$B$5)/7)+1) | H10: =IF(F10="","",F10*Configurações!$B$6+Configurações!$B$7) | I10: =IF(F10="","",F10*Configurações!$B$8) | K10: =IF(F10="","",IF(J10="Sim",-H10-G10,F10-G10-H10-I10)) | N10: =IF(OR(M10="",Configurações!$B$5=""),"",INT((M10-Configurações!$B$5)/7)+1)
B11: =IF(OR(A11="",Configurações!$B$5=""),"",INT((A11-Configurações!$B$5)/7)+1) | H11: =IF(F11="","",F11*Configurações!$B$6+Configurações!$B$7) | I11: =IF(F11="","",F11*Configurações!$B$8) | K11: =IF(F11="","",IF(J11="Sim",-H11-G11,F11-G11-H11-I11)) | N11: =IF(OR(M11="",Configurações!$B$5=""),"",INT((M11-Configurações!$B$5)/7)+1)
B12: =IF(OR(A12="",Configurações!$B$5=""),"",INT((A12-Configurações!$B$5)/7)+1) | H12: =IF(F12="","",F12*Configurações!$B$6+Configurações!$B$7) | I12: =IF(F12="","",F12*Configurações!$B$8) | K12: =IF(F12="","",IF(J12="Sim",-H12-G12,F12-G12-H12-I12)) | N12: =IF(OR(M12="",Configurações!$B$5=""),"",INT((M12-Configurações!$B$5)/7)+1)
B13: =IF(OR(A13="",Configurações!$B$5=""),"",INT((A13-Configurações!$B$5)/7)+1) | H13: =IF(F13="","",F13*Configurações!$B$6+Configurações!$B$7) | I13: =IF(F13="","",F13*Configurações!$B$8) | K13: =IF(F13="","",IF(J13="Sim",-H13-G13,F13-G13-H13-I13)) | N13: =IF(OR(M13="",Configurações!$B$5=""),"",INT((M13-Configurações!$B$5)/7)+1)
B14: =IF(OR(A14="",Configurações!$B$5=""),"",INT((A14-Configurações!$B$5)/7)+1) | H14: =IF(F14="","",F14*Configurações!$B$6+Configurações!$B$7) | I14: =IF(F14="","",F14*Configurações!$B$8) | K14: =IF(F14="","",IF(J14="Sim",-H14-G14,F14-G14-H14-I14)) | N14: =IF(OR(M14="",Configurações!$B$5=""),"",INT((M14-Configurações!$B$5)/7)+1)
B15: =IF(OR(A15="",Configurações!$B$5=""),"",INT((A15-Configurações!$B$5)/7)+1) | H15: =IF(F15="","",F15*Configurações!$B$6+Configurações!$B$7) | I15: =IF(F15="","",F15*Configurações!$B$8) | K15: =IF(F15="","",IF(J15="Sim",-H15-G15,F15-G15-H15-I15)) | N15: =IF(OR(M15="",Configurações!$B$5=""),"",INT((M15-Configurações!$B$5)/7)+1)
B16: =IF(OR(A16="",Configurações!$B$5=""),"",INT((A16-Configurações!$B$5)/7)+1) | H16: =IF(F16="","",F16*Configurações!$B$6+Configurações!$B$7) | I16: =IF(F16="","",F16*Configurações!$B$8) | K16: =IF(F16="","",IF(J16="Sim",-H16-G16,F16-G16-H16-I16)) | N16: =IF(OR(M16="",Configurações!$B$5=""),"",INT((M16-Configurações!$B$5)/7)+1)
... B104: =IF(OR(A104="",Configurações!$B$5=""),"",INT((A104-Configurações!$B$5)/7)+1) | H104: =IF(F104="","",F104*Configurações!$B$6+Configurações!$B$7) | I104: =IF(F104="","",F104*Configurações!$B$8) | K104: =IF(F104="","",IF(J104="Sim",-H104-G104,F104-G104-H104-I104)) | N104: =IF(OR(M104="",Configurações!$B$5=""),"",INT((M104-Configurações!$B$5)/7)+1)
B105: =IF(OR(A105="",Configurações!$B$5=""),"",INT((A105-Configurações!$B$5)/7)+1) | H105: =IF(F105="","",F105*Configurações!$B$6+Configurações!$B$7) | I105: =IF(F105="","",F105*Configurações!$B$8) | K105: =IF(F105="","",IF(J105="Sim",-H105-G105,F105-G105-H105-I105))
B106: =IF(OR(A106="",Configurações!$B$5=""),"",INT((A106-Configurações!$B$5)/7)+1) | H106: =IF(F106="","",F106*Configurações!$B$6+Configurações!$B$7) | I106: =IF(F106="","",F106*Configurações!$B$8) | K106: =IF(F106="","",IF(J106="Sim",-H106-G106,F106-G106-H106-I106))
B107: =IF(OR(A107="",Configurações!$B$5=""),"",INT((A107-Configurações!$B$5)/7)+1) | H107: =IF(F107="","",F107*Configurações!$B$6+Configurações!$B$7) | I107: =IF(F107="","",F107*Configurações!$B$8) | K107: =IF(F107="","",IF(J107="Sim",-H107-G107,F107-G107-H107-I107))
B108: =IF(OR(A108="",Configurações!$B$5=""),"",INT((A108-Configurações!$B$5)/7)+1) | H108: =IF(F108="","",F108*Configurações!$B$6+Configurações!$B$7) | I108: =IF(F108="","",F108*Configurações!$B$8) | K108: =IF(F108="","",IF(J108="Sim",-H108-G108,F108-G108-H108-I108))
B109: =IF(OR(A109="",Configurações!$B$5=""),"",INT((A109-Configurações!$B$5)/7)+1) | H109: =IF(F109="","",F109*Configurações!$B$6+Configurações!$B$7) | I109: =IF(F109="","",F109*Configurações!$B$8) | K109: =IF(F109="","",IF(J109="Sim",-H109-G109,F109-G109-H109-I109))
B110: =IF(OR(A110="",Configurações!$B$5=""),"",INT((A110-Configurações!$B$5)/7)+1) | H110: =IF(F110="","",F110*Configurações!$B$6+Configurações!$B$7) | I110: =IF(F110="","",F110*Configurações!$B$8) | K110: =IF(F110="","",IF(J110="Sim",-H110-G110,F110-G110-H110-I110))
B111: =IF(OR(A111="",Configurações!$B$5=""),"",INT((A111-Configurações!$B$5)/7)+1) | H111: =IF(F111="","",F111*Configurações!$B$6+Configurações!$B$7) | I111: =IF(F111="","",F111*Configurações!$B$8) | K111: =IF(F111="","",IF(J111="Sim",-H111-G111,F111-G111-H111-I111))
B112: =IF(OR(A112="",Configurações!$B$5=""),"",INT((A112-Configurações!$B$5)/7)+1) | H112: =IF(F112="","",F112*Configurações!$B$6+Configurações!$B$7) | I112: =IF(F112="","",F112*Configurações!$B$8) | K112: =IF(F112="","",IF(J112="Sim",-H112-G112,F112-G112-H112-I112))
B113: =IF(OR(A113="",Configurações!$B$5=""),"",INT((A113-Configurações!$B$5)/7)+1) | H113: =IF(F113="","",F113*Configurações!$B$6+Configurações!$B$7) | I113: =IF(F113="","",F113*Configurações!$B$8) | K113: =IF(F113="","",IF(J113="Sim",-H113-G113,F113-G113-H113-I113))
B114: =IF(OR(A114="",Configurações!$B$5=""),"",INT((A114-Configurações!$B$5)/7)+1) | H114: =IF(F114="","",F114*Configurações!$B$6+Configurações!$B$7) | I114: =IF(F114="","",F114*Configurações!$B$8) | K114: =IF(F114="","",IF(J114="Sim",-H114-G114,F114-G114-H114-I114))
B115: =IF(OR(A115="",Configurações!$B$5=""),"",INT((A115-Configurações!$B$5)/7)+1) | H115: =IF(F115="","",F115*Configurações!$B$6+Configurações!$B$7) | I115: =IF(F115="","",F115*Configurações!$B$8) | K115: =IF(F115="","",IF(J115="Sim",-H115-G115,F115-G115-H115-I115))
B116: =IF(OR(A116="",Configurações!$B$5=""),"",INT((A116-Configurações!$B$5)/7)+1) | H116: =IF(F116="","",F116*Configurações!$B$6+Configurações!$B$7) | I116: =IF(F116="","",F116*Configurações!$B$8) | K116: =IF(F116="","",IF(J116="Sim",-H116-G116,F116-G116-H116-I116))
... B204: =IF(OR(A204="",Configurações!$B$5=""),"",INT((A204-Configurações!$B$5)/7)+1) | H204: =IF(F204="","",F204*Configurações!$B$6+Configurações!$B$7) | I204: =IF(F204="","",F204*Configurações!$B$8) | K204: =IF(F204="","",IF(J204="Sim",-H204-G204,F204-G204-H204-I204))

Sheet Tempo
A1: Tempo dedicado
A2: Anote os minutos por dia. Inclui conversas, conteúdo, produção e entrega.
A4: Data | B4: Semana | C4: Minutos | D4: No que trabalhou
B5: =IF(OR(A5="",Configurações!$B$5=""),"",INT((A5-Configurações!$B$5)/7)+1)
B6: =IF(OR(A6="",Configurações!$B$5=""),"",INT((A6-Configurações!$B$5)/7)+1)
B7: =IF(OR(A7="",Configurações!$B$5=""),"",INT((A7-Configurações!$B$5)/7)+1)
B8: =IF(OR(A8="",Configurações!$B$5=""),"",INT((A8-Configurações!$B$5)/7)+1)
B9: =IF(OR(A9="",Configurações!$B$5=""),"",INT((A9-Configurações!$B$5)/7)+1)
B10: =IF(OR(A10="",Configurações!$B$5=""),"",INT((A10-Configurações!$B$5)/7)+1)
B11: =IF(OR(A11="",Configurações!$B$5=""),"",INT((A11-Configurações!$B$5)/7)+1)
B12: =IF(OR(A12="",Configurações!$B$5=""),"",INT((A12-Configurações!$B$5)/7)+1)
B13: =IF(OR(A13="",Configurações!$B$5=""),"",INT((A13-Configurações!$B$5)/7)+1)
B14: =IF(OR(A14="",Configurações!$B$5=""),"",INT((A14-Configurações!$B$5)/7)+1)
B15: =IF(OR(A15="",Configurações!$B$5=""),"",INT((A15-Configurações!$B$5)/7)+1)
B16: =IF(OR(A16="",Configurações!$B$5=""),"",INT((A16-Configurações!$B$5)/7)+1)
... B124: =IF(OR(A124="",Configurações!$B$5=""),"",INT((A124-Configurações!$B$5)/7)+1)

Sheet Painel
A1: Painel
A2: Atualiza sozinho. Leia de cima para baixo: atividade, funil, dinheiro, diagnóstico.
A4: Semana | B4: Novos contatos | C4: Meta | D4: Responderam | E4: Conversas | F4: Propostas | G4: Vendas | H4: Resposta | I4: Conversa | J4: Proposta | K4: Fechamento | L4: Etapa mais fraca | M4: Horas | N4: Diagnóstico
A5: 1 | B5: =COUNTIF(Contatos!$B$5:$B$504,A5) | C5: =Configurações!$B$9 | D5: =COUNTIFS(Contatos!$B$5:$B$504,A5,Contatos!$G$5:$G$504,">="&2) | E5: =COUNTIFS(Contatos!$B$5:$B$504,A5,Contatos!$G$5:$G$504,">="&3) | F5: =COUNTIFS(Contatos!$B$5:$B$504,A5,Contatos!$G$5:$G$504,">="&4) | G5: =COUNTIFS(Contatos!$B$5:$B$504,A5,Contatos!$G$5:$G$504,">="&5) | H5: =IF(B5=0,"",D5/B5) | I5: =IF(D5=0,"",E5/D5) | J5: =IF(E5=0,"",F5/E5) | K5: =IF(F5=0,"",G5/F5) | L5: =IF(B5=0,"",IF(D5=0,"Resposta",IF(E5=0,"Conversa",IF(F5=0,"Proposta",IF(G5=0,"Fechamento",INDEX({"Resposta","Conversa","Proposta","Fechamento"},MATCH(MIN(H5:K5),H5:K5,0))))))) | M5: =SUMIF(Tempo!$B$5:$B$124,A5,Tempo!$C$5:$C$124)/60 | N5: =IF(B5=0,"",IF(B5<C5,"Atividade abaixo da meta: antes de mudar a oferta, aumente os contatos. ","")&IF(L5="Resposta","Poucas respostas: revise público, canal e personalização da 1ª mensagem.",IF(L5="Conversa","Respondem sem interesse: fale com quem já mostrou o problema e deixe o benefício mais claro.",IF(L5="Proposta","Conversas não viram proposta: conecte a solução ao que a pessoa disse e pergunte o prazo.",IF(L5="Fechamento","Propostas sem venda: mostre demonstração, ofereça garantia simples e facilite o pagamento.","")))))
A6: 2 | B6: =COUNTIF(Contatos!$B$5:$B$504,A6) | C6: =Configurações!$B$9 | D6: =COUNTIFS(Contatos!$B$5:$B$504,A6,Contatos!$G$5:$G$504,">="&2) | E6: =COUNTIFS(Contatos!$B$5:$B$504,A6,Contatos!$G$5:$G$504,">="&3) | F6: =COUNTIFS(Contatos!$B$5:$B$504,A6,Contatos!$G$5:$G$504,">="&4) | G6: =COUNTIFS(Contatos!$B$5:$B$504,A6,Contatos!$G$5:$G$504,">="&5) | H6: =IF(B6=0,"",D6/B6) | I6: =IF(D6=0,"",E6/D6) | J6: =IF(E6=0,"",F6/E6) | K6: =IF(F6=0,"",G6/F6) | L6: =IF(B6=0,"",IF(D6=0,"Resposta",IF(E6=0,"Conversa",IF(F6=0,"Proposta",IF(G6=0,"Fechamento",INDEX({"Resposta","Conversa","Proposta","Fechamento"},MATCH(MIN(H6:K6),H6:K6,0))))))) | M6: =SUMIF(Tempo!$B$5:$B$124,A6,Tempo!$C$5:$C$124)/60 | N6: =IF(B6=0,"",IF(B6<C6,"Atividade abaixo da meta: antes de mudar a oferta, aumente os contatos. ","")&IF(L6="Resposta","Poucas respostas: revise público, canal e personalização da 1ª mensagem.",IF(L6="Conversa","Respondem sem interesse: fale com quem já mostrou o problema e deixe o benefício mais claro.",IF(L6="Proposta","Conversas não viram proposta: conecte a solução ao que a pessoa disse e pergunte o prazo.",IF(L6="Fechamento","Propostas sem venda: mostre demonstração, ofereça garantia simples e facilite o pagamento.","")))))
A7: 3 | B7: =COUNTIF(Contatos!$B$5:$B$504,A7) | C7: =Configurações!$B$9 | D7: =COUNTIFS(Contatos!$B$5:$B$504,A7,Contatos!$G$5:$G$504,">="&2) | E7: =COUNTIFS(Contatos!$B$5:$B$504,A7,Contatos!$G$5:$G$504,">="&3) | F7: =COUNTIFS(Contatos!$B$5:$B$504,A7,Contatos!$G$5:$G$504,">="&4) | G7: =COUNTIFS(Contatos!$B$5:$B$504,A7,Contatos!$G$5:$G$504,">="&5) | H7: =IF(B7=0,"",D7/B7) | I7: =IF(D7=0,"",E7/D7) | J7: =IF(E7=0,"",F7/E7) | K7: =IF(F7=0,"",G7/F7) | L7: =IF(B7=0,"",IF(D7=0,"Resposta",IF(E7=0,"Conversa",IF(F7=0,"Proposta",IF(G7=0,"Fechamento",INDEX({"Resposta","Conversa","Proposta","Fechamento"},MATCH(MIN(H7:K7),H7:K7,0))))))) | M7: =SUMIF(Tempo!$B$5:$B$124,A7,Tempo!$C$5:$C$124)/60 | N7: =IF(B7=0,"",IF(B7<C7,"Atividade abaixo da meta: antes de mudar a oferta, aumente os contatos. ","")&IF(L7="Resposta","Poucas respostas: revise público, canal e personalização da 1ª mensagem.",IF(L7="Conversa","Respondem sem interesse: fale com quem já mostrou o problema e deixe o benefício mais claro.",IF(L7="Proposta","Conversas não viram proposta: conecte a solução ao que a pessoa disse e pergunte o prazo.",IF(L7="Fechamento","Propostas sem venda: mostre demonstração, ofereça garantia simples e facilite o pagamento.","")))))
A8: 4 | B8: =COUNTIF(Contatos!$B$5:$B$504,A8) | C8: =Configurações!$B$9 | D8: =COUNTIFS(Contatos!$B$5:$B$504,A8,Contatos!$G$5:$G$504,">="&2) | E8: =COUNTIFS(Contatos!$B$5:$B$504,A8,Contatos!$G$5:$G$504,">="&3) | F8: =COUNTIFS(Contatos!$B$5:$B$504,A8,Contatos!$G$5:$G$504,">="&4) | G8: =COUNTIFS(Contatos!$B$5:$B$504,A8,Contatos!$G$5:$G$504,">="&5) | H8: =IF(B8=0,"",D8/B8) | I8: =IF(D8=0,"",E8/D8) | J8: =IF(E8=0,"",F8/E8) | K8: =IF(F8=0,"",G8/F8) | L8: =IF(B8=0,"",IF(D8=0,"Resposta",IF(E8=0,"Conversa",IF(F8=0,"Proposta",IF(G8=0,"Fechamento",INDEX({"Resposta","Conversa","Proposta","Fechamento"},MATCH(MIN(H8:K8),H8:K8,0))))))) | M8: =SUMIF(Tempo!$B$5:$B$124,A8,Tempo!$C$5:$C$124)/60 | N8: =IF(B8=0,"",IF(B8<C8,"Atividade abaixo da meta: antes de mudar a oferta, aumente os contatos. ","")&IF(L8="Resposta","Poucas respostas: revise público, canal e personalização da 1ª mensagem.",IF(L8="Conversa","Respondem sem interesse: fale com quem já mostrou o problema e deixe o benefício mais claro.",IF(L8="Proposta","Conversas não viram proposta: conecte a solução ao que a pessoa disse e pergunte o prazo.",IF(L8="Fechamento","Propostas sem venda: mostre demonstração, ofereça garantia simples e facilite o pagamento.","")))))
A9: 5 | B9: =COUNTIF(Contatos!$B$5:$B$504,A9) | C9: =Configurações!$B$9 | D9: =COUNTIFS(Contatos!$B$5:$B$504,A9,Contatos!$G$5:$G$504,">="&2) | E9: =COUNTIFS(Contatos!$B$5:$B$504,A9,Contatos!$G$5:$G$504,">="&3) | F9: =COUNTIFS(Contatos!$B$5:$B$504,A9,Contatos!$G$5:$G$504,">="&4) | G9: =COUNTIFS(Contatos!$B$5:$B$504,A9,Contatos!$G$5:$G$504,">="&5) | H9: =IF(B9=0,"",D9/B9) | I9: =IF(D9=0,"",E9/D9) | J9: =IF(E9=0,"",F9/E9) | K9: =IF(F9=0,"",G9/F9) | L9: =IF(B9=0,"",IF(D9=0,"Resposta",IF(E9=0,"Conversa",IF(F9=0,"Proposta",IF(G9=0,"Fechamento",INDEX({"Resposta","Conversa","Proposta","Fechamento"},MATCH(MIN(H9:K9),H9:K9,0))))))) | M9: =SUMIF(Tempo!$B$5:$B$124,A9,Tempo!$C$5:$C$124)/60 | N9: =IF(B9=0,"",IF(B9<C9,"Atividade abaixo da meta: antes de mudar a oferta, aumente os contatos. ","")&IF(L9="Resposta","Poucas respostas: revise público, canal e personalização da 1ª mensagem.",IF(L9="Conversa","Respondem sem interesse: fale com quem já mostrou o problema e deixe o benefício mais claro.",IF(L9="Proposta","Conversas não viram proposta: conecte a solução ao que a pessoa disse e pergunte o prazo.",IF(L9="Fechamento","Propostas sem venda: mostre demonstração, ofereça garantia simples e facilite o pagamento.","")))))
A10: 6 | B10: =COUNTIF(Contatos!$B$5:$B$504,A10) | C10: =Configurações!$B$9 | D10: =COUNTIFS(Contatos!$B$5:$B$504,A10,Contatos!$G$5:$G$504,">="&2) | E10: =COUNTIFS(Contatos!$B$5:$B$504,A10,Contatos!$G$5:$G$504,">="&3) | F10: =COUNTIFS(Contatos!$B$5:$B$504,A10,Contatos!$G$5:$G$504,">="&4) | G10: =COUNTIFS(Contatos!$B$5:$B$504,A10,Contatos!$G$5:$G$504,">="&5) | H10: =IF(B10=0,"",D10/B10) | I10: =IF(D10=0,"",E10/D10) | J10: =IF(E10=0,"",F10/E10) | K10: =IF(F10=0,"",G10/F10) | L10: =IF(B10=0,"",IF(D10=0,"Resposta",IF(E10=0,"Conversa",IF(F10=0,"Proposta",IF(G10=0,"Fechamento",INDEX({"Resposta","Conversa","Proposta","Fechamento"},MATCH(MIN(H10:K10),H10:K10,0))))))) | M10: =SUMIF(Tempo!$B$5:$B$124,A10,Tempo!$C$5:$C$124)/60 | N10: =IF(B10=0,"",IF(B10<C10,"Atividade abaixo da meta: antes de mudar a oferta, aumente os contatos. ","")&IF(L10="Resposta","Poucas respostas: revise público, canal e personalização da 1ª mensagem.",IF(L10="Conversa","Respondem sem interesse: fale com quem já mostrou o problema e deixe o benefício mais claro.",IF(L10="Proposta","Conversas não viram proposta: conecte a solução ao que a pessoa disse e pergunte o prazo.",IF(L10="Fechamento","Propostas sem venda: mostre demonstração, ofereça garantia simples e facilite o pagamento.","")))))
A11: 7 | B11: =COUNTIF(Contatos!$B$5:$B$504,A11) | C11: =Configurações!$B$9 | D11: =COUNTIFS(Contatos!$B$5:$B$504,A11,Contatos!$G$5:$G$504,">="&2) | E11: =COUNTIFS(Contatos!$B$5:$B$504,A11,Contatos!$G$5:$G$504,">="&3) | F11: =COUNTIFS(Contatos!$B$5:$B$504,A11,Contatos!$G$5:$G$504,">="&4) | G11: =COUNTIFS(Contatos!$B$5:$B$504,A11,Contatos!$G$5:$G$504,">="&5) | H11: =IF(B11=0,"",D11/B11) | I11: =IF(D11=0,"",E11/D11) | J11: =IF(E11=0,"",F11/E11) | K11: =IF(F11=0,"",G11/F11) | L11: =IF(B11=0,"",IF(D11=0,"Resposta",IF(E11=0,"Conversa",IF(F11=0,"Proposta",IF(G11=0,"Fechamento",INDEX({"Resposta","Conversa","Proposta","Fechamento"},MATCH(MIN(H11:K11),H11:K11,0))))))) | M11: =SUMIF(Tempo!$B$5:$B$124,A11,Tempo!$C$5:$C$124)/60 | N11: =IF(B11=0,"",IF(B11<C11,"Atividade abaixo da meta: antes de mudar a oferta, aumente os contatos. ","")&IF(L11="Resposta","Poucas respostas: revise público, canal e personalização da 1ª mensagem.",IF(L11="Conversa","Respondem sem interesse: fale com quem já mostrou o problema e deixe o benefício mais claro.",IF(L11="Proposta","Conversas não viram proposta: conecte a solução ao que a pessoa disse e pergunte o prazo.",IF(L11="Fechamento","Propostas sem venda: mostre demonstração, ofereça garantia simples e facilite o pagamento.","")))))
A12: 8 | B12: =COUNTIF(Contatos!$B$5:$B$504,A12) | C12: =Configurações!$B$9 | D12: =COUNTIFS(Contatos!$B$5:$B$504,A12,Contatos!$G$5:$G$504,">="&2) | E12: =COUNTIFS(Contatos!$B$5:$B$504,A12,Contatos!$G$5:$G$504,">="&3) | F12: =COUNTIFS(Contatos!$B$5:$B$504,A12,Contatos!$G$5:$G$504,">="&4) | G12: =COUNTIFS(Contatos!$B$5:$B$504,A12,Contatos!$G$5:$G$504,">="&5) | H12: =IF(B12=0,"",D12/B12) | I12: =IF(D12=0,"",E12/D12) | J12: =IF(E12=0,"",F12/E12) | K12: =IF(F12=0,"",G12/F12) | L12: =IF(B12=0,"",IF(D12=0,"Resposta",IF(E12=0,"Conversa",IF(F12=0,"Proposta",IF(G12=0,"Fechamento",INDEX({"Resposta","Conversa","Proposta","Fechamento"},MATCH(MIN(H12:K12),H12:K12,0))))))) | M12: =SUMIF(Tempo!$B$5:$B$124,A12,Tempo!$C$5:$C$124)/60 | N12: =IF(B12=0,"",IF(B12<C12,"Atividade abaixo da meta: antes de mudar a oferta, aumente os contatos. ","")&IF(L12="Resposta","Poucas respostas: revise público, canal e personalização da 1ª mensagem.",IF(L12="Conversa","Respondem sem interesse: fale com quem já mostrou o problema e deixe o benefício mais claro.",IF(L12="Proposta","Conversas não viram proposta: conecte a solução ao que a pessoa disse e pergunte o prazo.",IF(L12="Fechamento","Propostas sem venda: mostre demonstração, ofereça garantia simples e facilite o pagamento.","")))))
A13: 9 | B13: =COUNTIF(Contatos!$B$5:$B$504,A13) | C13: =Configurações!$B$9 | D13: =COUNTIFS(Contatos!$B$5:$B$504,A13,Contatos!$G$5:$G$504,">="&2) | E13: =COUNTIFS(Contatos!$B$5:$B$504,A13,Contatos!$G$5:$G$504,">="&3) | F13: =COUNTIFS(Contatos!$B$5:$B$504,A13,Contatos!$G$5:$G$504,">="&4) | G13: =COUNTIFS(Contatos!$B$5:$B$504,A13,Contatos!$G$5:$G$504,">="&5) | H13: =IF(B13=0,"",D13/B13) | I13: =IF(D13=0,"",E13/D13) | J13: =IF(E13=0,"",F13/E13) | K13: =IF(F13=0,"",G13/F13) | L13: =IF(B13=0,"",IF(D13=0,"Resposta",IF(E13=0,"Conversa",IF(F13=0,"Proposta",IF(G13=0,"Fechamento",INDEX({"Resposta","Conversa","Proposta","Fechamento"},MATCH(MIN(H13:K13),H13:K13,0))))))) | M13: =SUMIF(Tempo!$B$5:$B$124,A13,Tempo!$C$5:$C$124)/60 | N13: =IF(B13=0,"",IF(B13<C13,"Atividade abaixo da meta: antes de mudar a oferta, aumente os contatos. ","")&IF(L13="Resposta","Poucas respostas: revise público, canal e personalização da 1ª mensagem.",IF(L13="Conversa","Respondem sem interesse: fale com quem já mostrou o problema e deixe o benefício mais claro.",IF(L13="Proposta","Conversas não viram proposta: conecte a solução ao que a pessoa disse e pergunte o prazo.",IF(L13="Fechamento","Propostas sem venda: mostre demonstração, ofereça garantia simples e facilite o pagamento.","")))))
A14: 10 | B14: =COUNTIF(Contatos!$B$5:$B$504,A14) | C14: =Configurações!$B$9 | D14: =COUNTIFS(Contatos!$B$5:$B$504,A14,Contatos!$G$5:$G$504,">="&2) | E14: =COUNTIFS(Contatos!$B$5:$B$504,A14,Contatos!$G$5:$G$504,">="&3) | F14: =COUNTIFS(Contatos!$B$5:$B$504,A14,Contatos!$G$5:$G$504,">="&4) | G14: =COUNTIFS(Contatos!$B$5:$B$504,A14,Contatos!$G$5:$G$504,">="&5) | H14: =IF(B14=0,"",D14/B14) | I14: =IF(D14=0,"",E14/D14) | J14: =IF(E14=0,"",F14/E14) | K14: =IF(F14=0,"",G14/F14) | L14: =IF(B14=0,"",IF(D14=0,"Resposta",IF(E14=0,"Conversa",IF(F14=0,"Proposta",IF(G14=0,"Fechamento",INDEX({"Resposta","Conversa","Proposta","Fechamento"},MATCH(MIN(H14:K14),H14:K14,0))))))) | M14: =SUMIF(Tempo!$B$5:$B$124,A14,Tempo!$C$5:$C$124)/60 | N14: =IF(B14=0,"",IF(B14<C14,"Atividade abaixo da meta: antes de mudar a oferta, aumente os contatos. ","")&IF(L14="Resposta","Poucas respostas: revise público, canal e personalização da 1ª mensagem.",IF(L14="Conversa","Respondem sem interesse: fale com quem já mostrou o problema e deixe o benefício mais claro.",IF(L14="Proposta","Conversas não viram proposta: conecte a solução ao que a pessoa disse e pergunte o prazo.",IF(L14="Fechamento","Propostas sem venda: mostre demonstração, ofereça garantia simples e facilite o pagamento.","")))))
A15: 11 | B15: =COUNTIF(Contatos!$B$5:$B$504,A15) | C15: =Configurações!$B$9 | D15: =COUNTIFS(Contatos!$B$5:$B$504,A15,Contatos!$G$5:$G$504,">="&2) | E15: =COUNTIFS(Contatos!$B$5:$B$504,A15,Contatos!$G$5:$G$504,">="&3) | F15: =COUNTIFS(Contatos!$B$5:$B$504,A15,Contatos!$G$5:$G$504,">="&4) | G15: =COUNTIFS(Contatos!$B$5:$B$504,A15,Contatos!$G$5:$G$504,">="&5) | H15: =IF(B15=0,"",D15/B15) | I15: =IF(D15=0,"",E15/D15) | J15: =IF(E15=0,"",F15/E15) | K15: =IF(F15=0,"",G15/F15) | L15: =IF(B15=0,"",IF(D15=0,"Resposta",IF(E15=0,"Conversa",IF(F15=0,"Proposta",IF(G15=0,"Fechamento",INDEX({"Resposta","Conversa","Proposta","Fechamento"},MATCH(MIN(H15:K15),H15:K15,0))))))) | M15: =SUMIF(Tempo!$B$5:$B$124,A15,Tempo!$C$5:$C$124)/60 | N15: =IF(B15=0,"",IF(B15<C15,"Atividade abaixo da meta: antes de mudar a oferta, aumente os contatos. ","")&IF(L15="Resposta","Poucas respostas: revise público, canal e personalização da 1ª mensagem.",IF(L15="Conversa","Respondem sem interesse: fale com quem já mostrou o problema e deixe o benefício mais claro.",IF(L15="Proposta","Conversas não viram proposta: conecte a solução ao que a pessoa disse e pergunte o prazo.",IF(L15="Fechamento","Propostas sem venda: mostre demonstração, ofereça garantia simples e facilite o pagamento.","")))))
A16: 12 | B16: =COUNTIF(Contatos!$B$5:$B$504,A16) | C16: =Configurações!$B$9 | D16: =COUNTIFS(Contatos!$B$5:$B$504,A16,Contatos!$G$5:$G$504,">="&2) | E16: =COUNTIFS(Contatos!$B$5:$B$504,A16,Contatos!$G$5:$G$504,">="&3) | F16: =COUNTIFS(Contatos!$B$5:$B$504,A16,Contatos!$G$5:$G$504,">="&4) | G16: =COUNTIFS(Contatos!$B$5:$B$504,A16,Contatos!$G$5:$G$504,">="&5) | H16: =IF(B16=0,"",D16/B16) | I16: =IF(D16=0,"",E16/D16) | J16: =IF(E16=0,"",F16/E16) | K16: =IF(F16=0,"",G16/F16) | L16: =IF(B16=0,"",IF(D16=0,"Resposta",IF(E16=0,"Conversa",IF(F16=0,"Proposta",IF(G16=0,"Fechamento",INDEX({"Resposta","Conversa","Proposta","Fechamento"},MATCH(MIN(H16:K16),H16:K16,0))))))) | M16: =SUMIF(Tempo!$B$5:$B$124,A16,Tempo!$C$5:$C$124)/60 | N16: =IF(B16=0,"",IF(B16<C16,"Atividade abaixo da meta: antes de mudar a oferta, aumente os contatos. ","")&IF(L16="Resposta","Poucas respostas: revise público, canal e personalização da 1ª mensagem.",IF(L16="Conversa","Respondem sem interesse: fale com quem já mostrou o problema e deixe o benefício mais claro.",IF(L16="Proposta","Conversas não viram proposta: conecte a solução ao que a pessoa disse e pergunte o prazo.",IF(L16="Fechamento","Propostas sem venda: mostre demonstração, ofereça garantia simples e facilite o pagamento.","")))))
A18: Funil acumulado | B18: Pessoas | C18: % do topo
A19: Contatados | B19: =COUNTIF(Contatos!$G$5:$G$504,">="&1) | C19: =IF($B$19=0,"",B19/$B$19)
A20: Responderam | B20: =COUNTIF(Contatos!$G$5:$G$504,">="&2) | C20: =IF($B$19=0,"",B20/$B$19)
A21: Conversa | B21: =COUNTIF(Contatos!$G$5:$G$504,">="&3) | C21: =IF($B$19=0,"",B21/$B$19)
A22: Proposta | B22: =COUNTIF(Contatos!$G$5:$G$504,">="&4) | C22: =IF($B$19=0,"",B22/$B$19)
A23: Venda | B23: =COUNTIF(Contatos!$G$5:$G$504,">="&5) | C23: =IF($B$19=0,"",B23/$B$19)
A26: Canal | B26: Contatos | C26: Responderam | D26: Vendas | E26: Taxa de resposta | F26: Receita (R$)
A27: =Configurações!A15 | B27: =COUNTIF(Contatos!$D$5:$D$504,A27) | C27: =COUNTIFS(Contatos!$D$5:$D$504,A27,Contatos!$G$5:$G$504,">=2") | D27: =COUNTIFS(Contatos!$D$5:$D$504,A27,Contatos!$G$5:$G$504,5) | E27: =IF(B27=0,"",C27/B27) | F27: =SUMIFS('Vendas e custos'!$F$5:$F$204,'Vendas e custos'!$D$5:$D$204,A27,'Vendas e custos'!$J$5:$J$204,"<>Sim")
A28: =Configurações!A16 | B28: =COUNTIF(Contatos!$D$5:$D$504,A28) | C28: =COUNTIFS(Contatos!$D$5:$D$504,A28,Contatos!$G$5:$G$504,">=2") | D28: =COUNTIFS(Contatos!$D$5:$D$504,A28,Contatos!$G$5:$G$504,5) | E28: =IF(B28=0,"",C28/B28) | F28: =SUMIFS('Vendas e custos'!$F$5:$F$204,'Vendas e custos'!$D$5:$D$204,A28,'Vendas e custos'!$J$5:$J$204,"<>Sim")
A29: =Configurações!A17 | B29: =COUNTIF(Contatos!$D$5:$D$504,A29) | C29: =COUNTIFS(Contatos!$D$5:$D$504,A29,Contatos!$G$5:$G$504,">=2") | D29: =COUNTIFS(Contatos!$D$5:$D$504,A29,Contatos!$G$5:$G$504,5) | E29: =IF(B29=0,"",C29/B29) | F29: =SUMIFS('Vendas e custos'!$F$5:$F$204,'Vendas e custos'!$D$5:$D$204,A29,'Vendas e custos'!$J$5:$J$204,"<>Sim")
A30: =Configurações!A18 | B30: =COUNTIF(Contatos!$D$5:$D$504,A30) | C30: =COUNTIFS(Contatos!$D$5:$D$504,A30,Contatos!$G$5:$G$504,">=2") | D30: =COUNTIFS(Contatos!$D$5:$D$504,A30,Contatos!$G$5:$G$504,5) | E30: =IF(B30=0,"",C30/B30) | F30: =SUMIFS('Vendas e custos'!$F$5:$F$204,'Vendas e custos'!$D$5:$D$204,A30,'Vendas e custos'!$J$5:$J$204,"<>Sim")
A31: =Configurações!A19 | B31: =COUNTIF(Contatos!$D$5:$D$504,A31) | C31: =COUNTIFS(Contatos!$D$5:$D$504,A31,Contatos!$G$5:$G$504,">=2") | D31: =COUNTIFS(Contatos!$D$5:$D$504,A31,Contatos!$G$5:$G$504,5) | E31: =IF(B31=0,"",C31/B31) | F31: =SUMIFS('Vendas e custos'!$F$5:$F$204,'Vendas e custos'!$D$5:$D$204,A31,'Vendas e custos'!$J$5:$J$204,"<>Sim")
A32: =Configurações!A20 | B32: =COUNTIF(Contatos!$D$5:$D$504,A32) | C32: =COUNTIFS(Contatos!$D$5:$D$504,A32,Contatos!$G$5:$G$504,">=2") | D32: =COUNTIFS(Contatos!$D$5:$D$504,A32,Contatos!$G$5:$G$504,5) | E32: =IF(B32=0,"",C32/B32) | F32: =SUMIFS('Vendas e custos'!$F$5:$F$204,'Vendas e custos'!$D$5:$D$204,A32,'Vendas e custos'!$J$5:$J$204,"<>Sim")
A33: =Configurações!A21 | B33: =COUNTIF(Contatos!$D$5:$D$504,A33) | C33: =COUNTIFS(Contatos!$D$5:$D$504,A33,Contatos!$G$5:$G$504,">=2") | D33: =COUNTIFS(Contatos!$D$5:$D$504,A33,Contatos!$G$5:$G$504,5) | E33: =IF(B33=0,"",C33/B33) | F33: =SUMIFS('Vendas e custos'!$F$5:$F$204,'Vendas e custos'!$D$5:$D$204,A33,'Vendas e custos'!$J$5:$J$204,"<>Sim")
A34: =Configurações!A22 | B34: =COUNTIF(Contatos!$D$5:$D$504,A34) | C34: =COUNTIFS(Contatos!$D$5:$D$504,A34,Contatos!$G$5:$G$504,">=2") | D34: =COUNTIFS(Contatos!$D$5:$D$504,A34,Contatos!$G$5:$G$504,5) | E34: =IF(B34=0,"",C34/B34) | F34: =SUMIFS('Vendas e custos'!$F$5:$F$204,'Vendas e custos'!$D$5:$D$204,A34,'Vendas e custos'!$J$5:$J$204,"<>Sim")
A37: Dinheiro (acumulado) | B37: Valor
A38: Receita bruta (sem reembolsos) | B38: =SUMIFS('Vendas e custos'!$F$5:$F$204,'Vendas e custos'!$J$5:$J$204,"<>Sim")
A39: Custos diretos das vendas | B39: =SUM('Vendas e custos'!$G$5:$G$204)
A40: Taxas pagas | B40: =SUM('Vendas e custos'!$H$5:$H$204)
A41: Impostos estimados | B41: =SUMIFS('Vendas e custos'!$I$5:$I$204,'Vendas e custos'!$J$5:$J$204,"<>Sim")
A42: Gastos gerais | B42: =SUM('Vendas e custos'!$Q$5:$Q$104)
A43: Resultado (o que sobrou) | B43: =B38-B39-B40-B41-B42
A44: Vendas confirmadas | B44: =COUNTIFS('Vendas e custos'!$F$5:$F$204,">0",'Vendas e custos'!$J$5:$J$204,"<>Sim")
A45: Reembolsos | B45: =COUNTIF('Vendas e custos'!$J$5:$J$204,"Sim")
A46: Ticket médio | B46: =IF(B44=0,"",B38/B44)
...
